Workbook

Sheet ANÁLISE
B3: SENA 2026
B4: DEMONST. FINANCEIRA
C5: JANEIRO | E5: FEVEREIRO | G5: MARÇO | I5: ABRIL | K5: MAIO | M5: JUNHO | O5: JULHO | Q5: AGOSTO | S5: SETEMBRO | U5: OUTUBRO | W5: NOVEMBRO | Y5: DEZEMBRO | AA5: 2026
C6: R$ | D6: % | E6: R$ | F6: % | G6: R$ | H6: % | I6: R$ | J6: % | K6: R$ | L6: % | M6: R$ | N6: % | O6: R$ | P6: % | Q6: R$ | R6: % | S6: R$ | T6: % | U6: R$ | V6: % | W6: R$ | X6: % | Y6: R$ | Z6: % | AA6: R$ | AB6: %
B7: Aluguel - Clientes | C7: =MVTO!F3 -> 19875.28 | D7: =C7/$C$12 -> 1 | E7: =MVTO!G3 -> 40161.63 | F7: =E7/$E$12 -> 1 | G7: =MVTO!H3 -> 38795.06 | H7: =G7/$G$12 -> 1 | I7: =MVTO!I3 -> 26231.38 | J7: =I7/$I$12 -> 1 | K7: =MVTO!J3 -> 51183.74 | L7: =K7/$K$12 -> 1 | M7: =MVTO!K3 -> 34086.27 | N7: =M7/$I$12 -> 1.2994463 | O7: =MVTO!L3 -> 40272.17 | P7: =O7/$I$12 -> 1.5352669 | Q7: =MVTO!M3 -> 0 | R7: =Q7/$G$12 -> 0 | S7: =MVTO!N3 -> 0 | T7: =S7/$G$12 -> 0 | U7: =MVTO!O3 -> 0 | V7: =U7/$G$12 -> 0 | W7: =MVTO!P3 -> 0 | X7: =W7/$G$12 -> 0 | Y7: =MVTO!Q3 -> 0 | Z7: =Y7/$C$12 -> 0 | AA7: =C7+E7+G7+I7+K7+M7+O7+Q7+S7+U7+W7+Y7 -> 250605.53 | AB7: =AA7/$AA$12 -> 1
B8: Aluguel - Und 01 | C8: =MVTO!F4 -> 25000 | D8: =C8/$C$12 -> 1.2578439 | E8: =MVTO!G4 -> 980250.35 | F8: =E8/$E$12 -> 24.407634 | G8: =MVTO!H4 -> 60836.15 | H8: =G8/$G$12 -> 1.5681417 | I8: =MVTO!I4 -> 2177 | J8: =I8/$I$12 -> 0.082992202 | K8: =MVTO!J4 -> 220742.97 | L8: =K8/$I$12 -> 8.4152252 | M8: =MVTO!K4 -> 40000 | N8: =M8/$I$12 -> 1.5248912 | O8: =MVTO!L4 -> 20000 | P8: =O8/$I$12 -> 0.76244559 | Q8: =MVTO!M4 -> 0 | R8: =Q8/$G$12 -> 0 | S8: =MVTO!N4 -> 0 | T8: =S8/$G$12 -> 0 | U8: =MVTO!O4 -> 0 | V8: =U8/$G$12 -> 0 | W8: =MVTO!P4 -> 0 | X8: =W8/$G$12 -> 0 | Y8: =MVTO!Q4 -> 0 | Z8: =Y8/$C$12 -> 0 | AA8: =C8+E8+G8+I8+K8+M8+O8+Q8+S8+U8+W8+Y8 -> 1349006.5 | AB8: =AA8/$AA$12 -> 5.3829876
B9: Aluguel - Und 02 | C9: =MVTO!F5 -> 100847.05 | D9: =C9/$C$12 -> 5.0739939 | E9: =MVTO!G5 -> 140045.89 | F9: =E9/$E$12 -> 3.4870569 | G9: =MVTO!H5 -> 342469.87 | H9: =G9/$G$12 -> 8.827667 | I9: =MVTO!I5 -> 12000 | J9: =I9/$I$12 -> 0.45746735 | K9: =MVTO!J5 -> 13425 | L9: =K9/$I$12 -> 0.5117916 | M9: =MVTO!K5 -> 233116.41 | N9: =M9/$I$12 -> 8.8869289 | O9: =MVTO!L5 -> 108332.31 | P9: =O9/$I$12 -> 4.1298746 | Q9: =MVTO!M5 -> 0 | R9: =Q9/$G$12 -> 0 | S9: =MVTO!N5 -> 0 | T9: =S9/$G$12 -> 0 | U9: =MVTO!O5 -> 0 | V9: =U9/$G$12 -> 0 | W9: =MVTO!P5 -> 0 | X9: =W9/$G$12 -> 0 | Y9: =MVTO!Q5 -> 0 | Z9: =Y9/$C$12 -> 0 | AA9: =C9+E9+G9+I9+K9+M9+O9+Q9+S9+U9+W9+Y9 -> 950236.53 | AB9: =AA9/$AA$12 -> 3.791762
B10: Aluguel - Und 03 | C10: =MVTO!F6 -> 0 | D10: =C10/$C$12 -> 0 | E10: =MVTO!G6 -> 173814.62 | F10: =E10/$E$12 -> 4.3278776 | G10: =MVTO!H6 -> 182344.9 | H10: =G10/$G$12 -> 4.7002093 | I10: =MVTO!I6 -> 74940.3 | J10: =I10/$I$12 -> 2.8568951 | K10: =MVTO!J6 -> 12000 | L10: =K10/$I$12 -> 0.45746735 | M10: =MVTO!K6 -> 92193.49 | N10: =M10/$I$12 -> 3.514626 | O10: =MVTO!L6 -> 162868.32 | P10: =O10/$I$12 -> 6.2089116 | Q10: =MVTO!M6 -> 0 | R10: =Q10/$G$12 -> 0 | S10: =MVTO!N6 -> 0 | T10: =S10/$G$12 -> 0 | U10: =MVTO!O6 -> 0 | V10: =U10/$G$12 -> 0 | W10: =MVTO!P6 -> 0 | X10: =W10/$G$12 -> 0 | Y10: =MVTO!Q6 -> 0 | Z10: =Y10/$C$12 -> 0 | AA10: =C10+E10+G10+I10+K10+M10+O10+Q10+S10+U10+W10+Y10 -> 698161.63 | AB10: =AA10/$AA$12 -> 2.7858987
B11: Aluguel - Und 04 | C11: =MVTO!F7 -> 0 | D11: =C11/$C$12 -> 0 | E11: =MVTO!G7 -> 100000 | F11: =E11/$E$12 -> 2.4899388 | G11: =MVTO!H7 -> 100000 | H11: =G11/$G$12 -> 2.5776478 | I11: =MVTO!I7 -> 0 | J11: =I11/$I$12 -> 0 | K11: =MVTO!J7 -> 100000 | L11: =K11/$I$12 -> 3.8122279 | M11: =MVTO!K7 -> 50000 | N11: =M11/$I$12 -> 1.906114 | O11: =MVTO!L7 -> 100000 | P11: =O11/$I$12 -> 3.8122279 | Q11: =MVTO!M7 -> 0 | R11: =Q11/$G$12 -> 0 | S11: =MVTO!N7 -> 0 | T11: =S11/$G$12 -> 0 | U11: =MVTO!O7 -> 0 | V11: =U11/$G$12 -> 0 | W11: =MVTO!P7 -> 0 | AA11: =C11+E11+G11+I11+K11+M11+O11+Q11+S11+U11+W11+Y11 -> 450000
B12: Serviços - Clientes | C12: =C7 -> 19875.28 | D12: =C12/$C$14 -> 0.13639145 | E12: =E7 -> 40161.63 | F12: =E12/$E$14 -> 0.028001395 | G12: =G7 -> 38795.06 | H12: =G12/$G$14 -> 0.05355135 | I12: =I7 -> 26231.38 | J12: =I12/$I$14 -> 0.22740945 | K12: =K7 -> 51183.74 | L12: =K12/$I$14 -> 0.44373061 | M12: =M7 -> 34086.27 | N12: =M12/$I$14 -> 0.29550637 | O12: =O7 -> 40272.17 | P12: =O12/$I$14 -> 0.34913421 | Q12: =Q7 -> 0 | R12: =Q12/$G$14 -> 0 | S12: =S7 -> 0 | T12: =S12/$G$14 -> 0 | U12: =U7 -> 0 | V12: =U12/$G$14 -> 0 | W12: =W7 -> 0 | X12: =W12/$G$14 -> 0 | Y12: =Y7 -> 0 | Z12: =Y12/$C$14 -> 0 | AA12: =C12+E12+G12+I12+K12+M12+O12+Q12+S12+U12+W12+Y12 -> 250605.53 | AB12: =AA12/$AA$14 -> 0.067767669
B13: Serviços - TJ | C13: =SUM(C8:C11) -> 125847.05 | D13: =C13/$C$14 -> 0.86360855 | E13: =SUM(E8:E11) -> 1394110.9 | F13: =E13/$E$14 -> 0.97199861 | G13: =SUM(G8:G11) -> 685650.92 | H13: =G13/$G$14 -> 0.94644865 | I13: =SUM(I8:I11) -> 89117.3 | J13: =I13/$I$14 -> 0.77259055 | K13: =SUM(K8:K11) -> 346167.97 | L13: =K13/$I$14 -> 3.0010571 | M13: =SUM(M8:M11) -> 415309.9 | N13: =M13/$I$14 -> 3.6004738 | O13: =SUM(O8:O11) -> 391200.63 | P13: =O13/$I$14 -> 3.3914617 | Q13: =SUM(Q8:Q11) -> 0 | R13: =Q13/$G$14 -> 0 | S13: =SUM(S8:S11) -> 0 | T13: =S13/$G$14 -> 0 | U13: =SUM(U8:U11) -> 0 | V13: =U13/$G$14 -> 0 | W13: =SUM(W8:W11) -> 0 | X13: =W13/$G$14 -> 0 | Y13: =SUM(Y8:Y11) -> 0 | Z13: =Y13/$C$14 -> 0 | AA13: =C13+E13+G13+I13+K13+M13+O13+Q13+S13+U13+W13+Y13 -> 3447404.6 | AB13: =AA13/$AA$14 -> 0.93223233
B14: Total Receitas Serviços | C14: =SUM(C12:C13) -> 145722.33 | D14: =SUM(D12:D13) -> 1 | E14: =SUM(E12:E13) -> 1434272.5 | F14: =SUM(F12:F13) -> 1 | G14: =SUM(G12:G13) -> 724445.98 | H14: =SUM(H12:H13) -> 1 | I14: =SUM(I12:I13) -> 115348.68 | J14: =SUM(J12:J13) -> 1 | ... Z14: =SUM(Z12:Z13) -> 0 | AA14: =C14+E14+G14+I14+K14+M14+O14+Q14+S14+U14+W14+Y14 -> 3698010.2 | AB14: =SUM(AB12:AB13) -> 1
B15: Impostos S/ Serviços | C15: =SUMIF(MVTO!$C$3:$C$72,"Imp_Receita",MVTO!$F$3:$F$72) -> 20540.01 | D15: =C15/$C$14 -> 0.14095307 | E15: =SUMIF(MVTO!$C$3:$C$72,"Imp_Receita",MVTO!$G$3:$G$72) -> 18169.35 | F15: =E15/$E$14 -> 0.01266799 | G15: =SUMIF(MVTO!$C$3:$C$72,"Imp_Receita",MVTO!$H$3:$H$72) -> 17598.97 | H15: =G15/$G$14 -> 0.024293005 | I15: =SUMIF(MVTO!$C$3:$C$72,"Imp_Receita",MVTO!$I$3:$I$72) -> 18497.11 | J15: =I15/$I$14 -> 0.16035823 | K15: =SUMIF(MVTO!$C$3:$C$72,"Imp_Receita",MVTO!$J$3:$J$72) -> 18618.72 | L15: =K15/$I$14 -> 0.16141251 | M15: =SUMIF(MVTO!$C$3:$C$72,"Imp_Receita",MVTO!$K$3:$K$72) -> 18723.36 | N15: =M15/$I$14 -> 0.16231967 | O15: =SUMIF(MVTO!$C$3:$C$72,"Imp_Receita",MVTO!$L$3:$L$72) -> 17509.6 | P15: =O15/$I$14 -> 0.15179714 | Q15: =SUMIF(MVTO!$C$3:$C$72,"Imp_Receita",MVTO!$M$3:$M$72) -> 0 | R15: =Q15/$G$14 -> 0 | S15: =SUMIF(MVTO!$C$3:$C$72,"Imp_Receita",MVTO!$N$3:$N$72) -> 0 | T15: =S15/$G$14 -> 0 | U15: =SUMIF(MVTO!$C$3:$C$72,"Imp_Receita",MVTO!$O$3:$O$72) -> 0 | V15: =U15/$G$14 -> 0 | W15: =SUMIF(MVTO!$C$3:$C$72,"Imp_Receita",MVTO!$P$3:$P$72) -> 0 | X15: =W15/$G$14 -> 0 | Y15: =SUMIF(MVTO!$C$3:$C$72,"Imp_Receita",MVTO!$Q$3:$Q$72) -> 0 | Z15: =Y15/$C$14 -> 0 | AA15: =C15+E15+G15+I15+K15+M15+O15+Q15+S15+U15+W15+Y15 -> 129657.12 | AB15: =AA15/$AA$14 -> 0.035061321
B16: Rec de Despesas | C16: =SUMIF(MVTO!$C$3:$C$72,"Rec_Despesa",MVTO!$F$3:$F$72) -> 0 | D16: =C16/$C$14 -> 0 | E16: =SUMIF(MVTO!$C$3:$C$72,"Rec_Despesa",MVTO!$G$3:$G$72) -> 0 | F16: =E16/$E$14 -> 0 | G16: =SUMIF(MVTO!$C$3:$C$72,"Rec_Despesa",MVTO!$H$3:$H$72) -> 0 | H16: =G16/$G$14 -> 0 | I16: =SUMIF(MVTO!$C$3:$C$72,"Rec_Despesa",MVTO!$I$3:$I$72) -> 0 | J16: =I16/$I$14 -> 0 | K16: =SUMIF(MVTO!$C$3:$C$72,"Rec_Despesa",MVTO!$J$3:$J$72) -> 0 | L16: =K16/$I$14 -> 0 | M16: =SUMIF(MVTO!$C$3:$C$72,"Rec_Despesa",MVTO!$K$3:$K$72) -> 0 | N16: =M16/$I$14 -> 0 | O16: =SUMIF(MVTO!$C$3:$C$72,"Rec_Despesa",MVTO!$L$3:$L$72) -> 0 | P16: =O16/$I$14 -> 0 | Q16: =SUMIF(MVTO!$C$3:$C$72,"Rec_Despesa",MVTO!$M$3:$M$72) -> 0 | R16: =Q16/$G$14 -> 0 | S16: =SUMIF(MVTO!$C$3:$C$72,"Rec_Despesa",MVTO!$N$3:$N$72) -> 0 | T16: =S16/$G$14 -> 0 | U16: =SUMIF(MVTO!$C$3:$C$72,"Rec_Despesa",MVTO!$O$3:$O$72) -> 0 | V16: =U16/$G$14 -> 0 | W16: =SUMIF(MVTO!$C$3:$C$72,"Rec_Despesa",MVTO!$P$3:$P$72) -> 0 | X16: =W16/$G$14 -> 0 | Y16: =SUMIF(MVTO!$C$3:$C$72,"Rec_Despesa",MVTO!$Q$3:$Q$72) -> 0 | Z16: =Y16/$C$14 -> 0 | AA16: =C16+E16+G16+I16+K16+M16+O16+Q16+S16+U16+W16+Y16 -> 0 | AB16: =AA16/$AA$14 -> 0
B17: Lucro Bruto | C17: =C14-C15+C16 -> 125182.32 | D17: =C17/$C$14 -> 0.85904693 | E17: =E14-E15+E16 -> 1416103.1 | F17: =E17/$E$14 -> 0.98733201 | G17: =G14-G15+G16 -> 706847.01 | H17: =G17/$G$14 -> 0.97570699 | I17: =I14-I15+I16 -> 96851.57 | J17: =I17/$I$14 -> 0.83964177 | K17: =K14-K15+K16 -> 378732.99 | L17: =K17/$I$14 -> 3.2833752 | M17: =M14-M15+M16 -> 430672.81 | N17: =M17/$I$14 -> 3.7336605 | O17: =O14-O15+O16 -> 413963.2 | P17: =O17/$I$14 -> 3.5887988 | Q17: =Q14-Q15+Q16 -> 0 | R17: =Q17/$G$14 -> 0 | S17: =S14-S15+S16 -> 0 | T17: =S17/$G$14 -> 0 | U17: =U14-U15+U16 -> 0 | V17: =U17/$G$14 -> 0 | W17: =W14-W15+W16 -> 0 | X17: =W17/$G$14 -> 0 | Y17: =Y14-Y15+Y16 -> 0 | Z17: =Y17/$C$14 -> 0 | AA17: =C17+E17+G17+I17+K17+M17+O17+Q17+S17+U17+W17+Y17 -> 3568353 | AB17: =AA17/$AA$14 -> 0.96493868
B18: Custos operacionais | C18: =SUM(C19:C24) -> 58258.9 | D18: =C18/$C$14 -> 0.39979391 | E18: =SUM(E19:E24) -> 93360.55 | F18: =E18/$E$14 -> 0.065092617 | G18: =SUM(G19:G24) -> 73693.08 | H18: =G18/$G$14 -> 0.10172336 | I18: =SUM(I19:I24) -> 64229.99 | J18: =I18/$I$14 -> 0.55683333 | K18: =SUM(K19:K24) -> 73113.22 | L18: =K18/$I$14 -> 0.63384531 | M18: =SUM(M19:M24) -> 76137.63 | N18: =M18/$I$14 -> 0.66006503 | O18: =SUM(O19:O24) -> 65424.67 | P18: =O18/$I$14 -> 0.56719045 | Q18: =SUM(Q19:Q24) -> 0 | R18: =Q18/$G$14 -> 0 | S18: =SUM(S19:S24) -> 0 | T18: =S18/$G$14 -> 0 | U18: =SUM(U19:U24) -> 0 | V18: =U18/$G$14 -> 0 | W18: =SUM(W19:W24) -> 0 | X18: =W18/$G$14 -> 0 | Y18: =SUM(Y19:Y24) -> 0 | Z18: =Y18/$C$14 -> 0 | AA18: =C18+E18+G18+I18+K18+M18+O18+Q18+S18+U18+W18+Y18 -> 504218.04 | AB18: =AA18/$AA$14 -> 0.13634847
B19: Alugueis | C19: =SUMIF(MVTO!$C$3:$C$72,"Aluguel",MVTO!$F$3:$F$72) -> 56764 | D19: =C19/$C$14 -> 0.38953536 | E19: =SUMIF(MVTO!$C$3:$C$72,"Aluguel",MVTO!$G$3:$G$72) -> 57185 | F19: =E19/$E$14 -> 0.039870388 | G19: =SUMIF(MVTO!$C$3:$C$72,"Aluguel",MVTO!$H$3:$H$72) -> 57185 | H19: =G19/$G$14 -> 0.078936182 | I19: =SUMIF(MVTO!$C$3:$C$72,"Aluguel",MVTO!$I$3:$I$72) -> 57185 | J19: =I19/$I$14 -> 0.49575773 | K19: =SUMIF(MVTO!$C$3:$C$72,"Aluguel",MVTO!$J$3:$J$72) -> 57251 | L19: =K19/$I$14 -> 0.49632991 | M19: =SUMIF(MVTO!$C$3:$C$72,"Aluguel",MVTO!$K$3:$K$72) -> 57251 | N19: =M19/$I$14 -> 0.49632991 | O19: =SUMIF(MVTO!$C$3:$C$72,"Aluguel",MVTO!$L$3:$L$72) -> 57251 | P19: =O19/$I$14 -> 0.49632991 | Q19: =SUMIF(MVTO!$C$3:$C$72,"Aluguel",MVTO!$M$3:$M$72) -> 0 | R19: =Q19/$G$14 -> 0 | S19: =SUMIF(MVTO!$C$3:$C$72,"Aluguel",MVTO!$N$3:$N$72) -> 0 | T19: =S19/$G$14 -> 0 | U19: =SUMIF(MVTO!$C$3:$C$72,"Aluguel",MVTO!$O$3:$O$72) -> 0 | V19: =U19/$G$14 -> 0 | W19: =SUMIF(MVTO!$C$3:$C$72,"Aluguel",MVTO!$P$3:$P$72) -> 0 | X19: =W19/$G$14 -> 0 | Y19: =SUMIF(MVTO!$C$3:$C$72,"Aluguel",MVTO!$Q$3:$Q$72) -> 0 | Z19: =Y19/$C$14 -> 0 | AA19: =C19+E19+G19+I19+K19+M19+O19+Q19+S19+U19+W19+Y19 -> 400072 | AB19: =AA19/$AA$14 -> 0.10818575
B20: Tributos | C20: =SUMIF(MVTO!$C$3:$C$72,"Tributário",MVTO!$F$3:$F$72) -> 307.8 | D20: =C20/$C$14 -> 0.0021122363 | E20: =SUMIF(MVTO!$C$3:$C$72,"Tributário",MVTO!$G$3:$G$72) -> 14959.05 | F20: =E20/$E$14 -> 0.010429713 | G20: =SUMIF(MVTO!$C$3:$C$72,"Tributário",MVTO!$H$3:$H$72) -> 8131.25 | H20: =G20/$G$14 -> 0.011224094 | I20: =SUMIF(MVTO!$C$3:$C$72,"Tributário",MVTO!$I$3:$I$72) -> 56.5 | J20: =I20/$I$14 -> 0.00048981922 | K20: =SUMIF(MVTO!$C$3:$C$72,"Tributário",MVTO!$J$3:$J$72) -> 10741.77 | L20: =K20/$I$14 -> 0.093124343 | M20: =SUMIF(MVTO!$C$3:$C$72,"Tributário",MVTO!$K$3:$K$72) -> 11410.06 | N20: =M20/$I$14 -> 0.098917994 | O20: =SUMIF(MVTO!$C$3:$C$72,"Tributário",MVTO!$L$3:$L$72) -> 2666.79 | P20: =O20/$I$14 -> 0.02311938 | Q20: =SUMIF(MVTO!$C$3:$C$72,"Tributário",MVTO!$M$3:$M$72) -> 0 | R20: =Q20/$G$14 -> 0 | S20: =SUMIF(MVTO!$C$3:$C$72,"Tributário",MVTO!$N$3:$N$72) -> 0 | T20: =S20/$G$14 -> 0 | U20: =SUMIF(MVTO!$C$3:$C$72,"Tributário",MVTO!$O$3:$O$72) -> 0 | V20: =U20/$G$14 -> 0 | W20: =SUMIF(MVTO!$C$3:$C$72,"Tributário",MVTO!$P$3:$P$72) -> 0 | X20: =W20/$G$14 -> 0 | Y20: =SUMIF(MVTO!$C$3:$C$72,"Tributário",MVTO!$Q$3:$Q$72) -> 0 | Z20: =Y20/$C$14 -> 0 | AA20: =C20+E20+G20+I20+K20+M20+O20+Q20+S20+U20+W20+Y20 -> 48273.22 | AB20: =AA20/$AA$14 -> 0.013053836 | EY20: v
B21: Água e Esgotos | C21: =SUMIF(MVTO!$C$3:$C$72,"Água",MVTO!$F$3:$F$72) -> 900.1 | D21: =C21/$C$14 -> 0.0061768159 | E21: =SUMIF(MVTO!$C$3:$C$72,"Água",MVTO!$G$3:$G$72) -> 1447.43 | F21: =E21/$E$14 -> 0.0010091736 | G21: =SUMIF(MVTO!$C$3:$C$72,"Água",MVTO!$H$3:$H$72) -> 984.75 | H21: =G21/$G$14 -> 0.0013593146 | I21: =SUMIF(MVTO!$C$3:$C$72,"Água",MVTO!$I$3:$I$72) -> 1022.8 | J21: =I21/$I$14 -> 0.0088670282 | K21: =SUMIF(MVTO!$C$3:$C$72,"Água",MVTO!$J$3:$J$72) -> 767.55 | L21: =K21/$I$14 -> 0.0066541724 | M21: =SUMIF(MVTO!$C$3:$C$72,"Água",MVTO!$K$3:$K$72) -> 1670.95 | N21: =M21/$I$14 -> 0.014486078 | O21: =SUMIF(MVTO!$C$3:$C$72,"Água",MVTO!$L$3:$L$72) -> 1314.24 | P21: =O21/$I$14 -> 0.011393628 | Q21: =SUMIF(MVTO!$C$3:$C$72,"Água",MVTO!$M$3:$M$72) -> 0 | R21: =Q21/$G$14 -> 0 | S21: =SUMIF(MVTO!$C$3:$C$72,"Água",MVTO!$N$3:$N$72) -> 0 | T21: =S21/$G$14 -> 0 | U21: =SUMIF(MVTO!$C$3:$C$72,"Água",MVTO!$O$3:$O$72) -> 0 | V21: =U21/$G$14 -> 0 | W21: =SUMIF(MVTO!$C$3:$C$72,"Água",MVTO!$P$3:$P$72) -> 0 | X21: =W21/$G$14 -> 0 | Y21: =SUMIF(MVTO!$C$3:$C$72,"Água",MVTO!$Q$3:$Q$72) -> 0 | Z21: =Y21/$C$14 -> 0 | AA21: =C21+E21+G21+I21+K21+M21+O21+Q21+S21+U21+W21+Y21 -> 8107.82 | AB21: =AA21/$AA$14 -> 0.0021924818
B22: Depósito Judicial | C22: =SUMIF(MVTO!$C$3:$C$72,"Dep_Judicial",MVTO!$F$3:$F$72) -> 0 | D22: =C22/$C$14 -> 0 | E22: =SUMIF(MVTO!$C$3:$C$72,"Dep_Judicial",MVTO!$G$3:$G$72) -> 0 | F22: =E22/$E$14 -> 0 | G22: =SUMIF(MVTO!$C$3:$C$72,"Dep_Judicial",MVTO!$H$3:$H$72) -> 0 | H22: =G22/$G$14 -> 0 | I22: =SUMIF(MVTO!$C$3:$C$72,"Dep_Judicial",MVTO!$I$3:$I$72) -> 0 | J22: =I22/$I$14 -> 0 | K22: =SUMIF(MVTO!$C$3:$C$72,"Dep_Judicial",MVTO!$J$3:$J$72) -> 0 | L22: =K22/$I$14 -> 0 | M22: =SUMIF(MVTO!$C$3:$C$72,"Dep_Judicial",MVTO!$K$3:$K$72) -> 0 | N22: =M22/$I$14 -> 0 | O22: =SUMIF(MVTO!$C$3:$C$72,"Dep_Judicial",MVTO!$L$3:$L$72) -> 0 | P22: =O22/$I$14 -> 0 | Q22: =SUMIF(MVTO!$C$3:$C$72,"Dep_Judicial",MVTO!$M$3:$M$72) -> 0 | R22: =Q22/$G$14 -> 0 | S22: =SUMIF(MVTO!$C$3:$C$72,"Dep_Judicial",MVTO!$N$3:$N$72) -> 0 | T22: =S22/$G$14 -> 0 | U22: =SUMIF(MVTO!$C$3:$C$72,"Dep_Judicial",MVTO!$O$3:$O$72) -> 0 | V22: =U22/$G$14 -> 0 | W22: =SUMIF(MVTO!$C$3:$C$72,"Dep_Judicial",MVTO!$P$3:$P$72) -> 0 | X22: =W22/$G$14 -> 0 | Y22: =SUMIF(MVTO!$C$3:$C$72,"Dep_Judicial",MVTO!$Q$3:$Q$72) -> 0 | Z22: =Y22/$C$14 -> 0 | AA22: =C22+E22+G22+I22+K22+M22+O22+Q22+S22+U22+W22+Y22 -> 0 | AB22: =AA22/$AA$14 -> 0
B23: Manutenção Imóvel | C23: =SUMIF(MVTO!$C$3:$C$72,"Desp_imovel",MVTO!$F$3:$F$72) -> 287 | D23: =C23/$C$14 -> 0.0019694991 | E23: =SUMIF(MVTO!$C$3:$C$72,"Desp_imovel",MVTO!$G$3:$G$72) -> 19769.07 | F23: =E23/$E$14 -> 0.013783343 | G23: =SUMIF(MVTO!$C$3:$C$72,"Desp_imovel",MVTO!$H$3:$H$72) -> 7392.08 | H23: =G23/$G$14 -> 0.01020377 | I23: =SUMIF(MVTO!$C$3:$C$72,"Desp_imovel",MVTO!$I$3:$I$72) -> 5965.69 | J23: =I23/$I$14 -> 0.051718754 | K23: =SUMIF(MVTO!$C$3:$C$72,"Desp_imovel",MVTO!$J$3:$J$72) -> 4352.9 | L23: =K23/$I$14 -> 0.037736886 | M23: =SUMIF(MVTO!$C$3:$C$72,"Desp_imovel",MVTO!$K$3:$K$72) -> 5805.62 | N23: =M23/$I$14 -> 0.050331048 | O23: =SUMIF(MVTO!$C$3:$C$72,"Desp_imovel",MVTO!$L$3:$L$72) -> 4192.64 | P23: =O23/$I$14 -> 0.036347533 | Q23: =SUMIF(MVTO!$C$3:$C$72,"Desp_imovel",MVTO!$M$3:$M$72) -> 0 | R23: =Q23/$G$14 -> 0 | S23: =SUMIF(MVTO!$C$3:$C$72,"Desp_imovel",MVTO!$N$3:$N$72) -> 0 | T23: =S23/$G$14 -> 0 | U23: =SUMIF(MVTO!$C$3:$C$72,"Desp_imovel",MVTO!$O$3:$O$72) -> 0 | V23: =U23/$G$14 -> 0 | W23: =SUMIF(MVTO!$C$3:$C$72,"Desp_imovel",MVTO!$P$3:$P$72) -> 0 | X23: =W23/$G$14 -> 0 | Y23: =SUMIF(MVTO!$C$3:$C$72,"Desp_imovel",MVTO!$Q$3:$Q$72) -> 0 | Z23: =Y23/$C$14 -> 0 | AA23: =C23+E23+G23+I23+K23+M23+O23+Q23+S23+U23+W23+Y23 -> 47765 | AB23: =AA23/$AA$14 -> 0.012916406
B24: Pessoal | C24: =SUMIF(MVTO!$C$3:$C$72,"Pessoal",MVTO!$F$3:$F$72) -> 0 | D24: =C24/$C$14 -> 0 | E24: =SUMIF(MVTO!$C$3:$C$72,"Pessoal",MVTO!$G$3:$G$72) -> 0 | F24: =E24/$E$14 -> 0 | G24: =SUMIF(MVTO!$C$3:$C$72,"Pessoal",MVTO!$H$3:$H$72) -> 0 | H24: =G24/$G$14 -> 0 | I24: =SUMIF(MVTO!$C$3:$C$72,"Pessoal",MVTO!$I$3:$I$72) -> 0 | J24: =I24/$I$14 -> 0 | K24: =SUMIF(MVTO!$C$3:$C$72,"Pessoal",MVTO!$J$3:$J$72) -> 0 | L24: =K24/$I$14 -> 0 | M24: =SUMIF(MVTO!$C$3:$C$72,"Pessoal",MVTO!$K$3:$K$72) -> 0 | N24: =M24/$I$14 -> 0 | O24: =SUMIF(MVTO!$C$3:$C$72,"Pessoal",MVTO!$L$3:$L$72) -> 0 | P24: =O24/$I$14 -> 0 | Q24: =SUMIF(MVTO!$C$3:$C$72,"Pessoal",MVTO!$M$3:$M$72) -> 0 | R24: =Q24/$G$14 -> 0 | S24: =SUMIF(MVTO!$C$3:$C$72,"Pessoal",MVTO!$N$3:$N$72) -> 0 | T24: =S24/$G$14 -> 0 | U24: =SUMIF(MVTO!$C$3:$C$72,"Pessoal",MVTO!$O$3:$O$72) -> 0 | V24: =U24/$G$14 -> 0 | W24: =SUMIF(MVTO!$C$3:$C$72,"Pessoal",MVTO!$P$3:$P$72) -> 0 | X24: =W24/$G$14 -> 0 | Y24: =SUMIF(MVTO!$C$3:$C$72,"Pessoal",MVTO!$Q$3:$Q$72) -> 0 | Z24: =Y24/$C$14 -> 0 | AA24: =C24+E24+G24+I24+K24+M24+O24+Q24+S24+U24+W24+Y24 -> 0 | AB24: =AA24/$AA$14 -> 0
B25: Lucro das operações | C25: =C17-C18 -> 66923.42 | D25: =C25/$C$14 -> 0.45925302 | E25: =E17-E18 -> 1322742.6 | F25: =E25/$E$14 -> 0.92223939 | G25: =G17-G18 -> 633153.93 | H25: =G25/$G$14 -> 0.87398363 | I25: =I17-I18 -> 32621.58 | J25: =I25/$I$14 -> 0.28280844 | K25: =K17-K18 -> 305619.77 | L25: =K25/$I$14 -> 2.6495298 | M25: =M17-M18 -> 354535.18 | N25: =M25/$I$14 -> 3.0735955 | O25: =O17-O18 -> 348538.53 | P25: =O25/$I$14 -> 3.0216083 | Q25: =Q17-Q18 -> 0 | R25: =Q25/$G$14 -> 0 | S25: =S17-S18 -> 0 | T25: =S25/$G$14 -> 0 | U25: =U17-U18 -> 0 | V25: =U25/$G$14 -> 0 | W25: =W17-W18 -> 0 | X25: =W25/$G$14 -> 0 | Y25: =Y17-Y18 -> 0 | Z25: =Y25/$C$14 -> 0 | AA25: =C25+E25+G25+I25+K25+M25+O25+Q25+S25+U25+W25+Y25 -> 3064135 | AB25: =AA25/$AA$14 -> 0.82859021
B26: Resultado Financeiro | C26: =SUMIF(MVTO!$C$3:$C$72,"Rec_Fin",MVTO!$F$3:$F$72)-SUMIF(MVTO!$C$3:$C$72,"Desp_Fin",MVTO!$F$3:$F$72) -> -1591.56 | D26: =C26/$C$14 -> -0.010921868 | E26: =SUMIF(MVTO!$C$3:$C$72,"Rec_Fin",MVTO!$G$3:$G$72)-SUMIF(MVTO!$C$3:$C$72,"Desp_Fin",MVTO!$G$3:$G$72) -> -14276.99 | F26: =E26/$E$14 -> -0.0099541685 | G26: =SUMIF(MVTO!$C$3:$C$72,"Rec_Fin",MVTO!$H$3:$H$72)-SUMIF(MVTO!$C$3:$C$72,"Desp_Fin",MVTO!$H$3:$H$72) -> 2353.2 | H26: =G26/$G$14 -> 0.0032482753 | I26: =SUMIF(MVTO!$C$3:$C$72,"Rec_Fin",MVTO!$I$3:$I$72)-SUMIF(MVTO!$C$3:$C$72,"Desp_Fin",MVTO!$I$3:$I$72) -> -2204.02 | J26: =I26/$I$14 -> -0.019107457 | K26: =SUMIF(MVTO!$C$3:$C$72,"Rec_Fin",MVTO!$J$3:$J$72)-SUMIF(MVTO!$C$3:$C$72,"Desp_Fin",MVTO!$J$3:$J$72) -> 731.82 | L26: =K26/$I$14 -> 0.0063444159 | M26: =SUMIF(MVTO!$C$3:$C$72,"Rec_Fin",MVTO!$K$3:$K$72)-SUMIF(MVTO!$C$3:$C$72,"Desp_Fin",MVTO!$K$3:$K$72) -> -1926 | N26: =M26/$I$14 -> -0.0166972 | O26: =SUMIF(MVTO!$C$3:$C$72,"Rec_Fin",MVTO!$L$3:$L$72)-SUMIF(MVTO!$C$3:$C$72,"Desp_Fin",MVTO!$L$3:$L$72) -> -25.33 | P26: =O26/$I$14 -> -0.00021959506 | Q26: =SUMIF(MVTO!$C$3:$C$72,"Rec_Fin",MVTO!$M$3:$M$72)-SUMIF(MVTO!$C$3:$C$72,"Desp_Fin",MVTO!$M$3:$M$72) -> 0 | R26: =Q26/$G$14 -> 0 | S26: =SUMIF(MVTO!$C$3:$C$72,"Rec_Fin",MVTO!$N$3:$N$72)-SUMIF(MVTO!$C$3:$C$72,"Desp_Fin",MVTO!$N$3:$N$72) -> 0 | T26: =S26/$G$14 -> 0 | U26: =SUMIF(MVTO!$C$3:$C$72,"Rec_Fin",MVTO!$O$3:$O$72)-SUMIF(MVTO!$C$3:$C$72,"Desp_Fin",MVTO!$O$3:$O$72) -> 0 | V26: =U26/$G$14 -> 0 | W26: =SUMIF(MVTO!$C$3:$C$72,"Rec_Fin",MVTO!$P$3:$P$72)-SUMIF(MVTO!$C$3:$C$72,"Desp_Fin",MVTO!$P$3:$P$72) -> 0 | X26: =W26/$G$14 -> 0 | Y26: =SUMIF(MVTO!$C$3:$C$72,"Rec_Fin",MVTO!$Q$3:$Q$72)-SUMIF(MVTO!$C$3:$C$72,"Desp_Fin",MVTO!$Q$3:$Q$72) -> 0 | Z26: =Y26/$C$14 -> 0 | AA26: =C26+E26+G26+I26+K26+M26+O26+Q26+S26+U26+W26+Y26 -> -16938.88 | AB26: =AA26/$AA$14 -> -0.0045805391
B27: I.R | C27: =SUMIF(MVTO!$C$3:$C$72,"Imp_IR",MVTO!$F$3:$F$72) -> 56026.96 | D27: =C27/$C$14 -> 0.38447752 | E27: =SUMIF(MVTO!$C$3:$C$72,"Imp_IR",MVTO!$G$3:$G$72) -> 56026.96 | F27: =E27/$E$14 -> 0.039062982 | G27: =SUMIF(MVTO!$C$3:$C$72,"Imp_IR",MVTO!$H$3:$H$72) -> 56026.96 | H27: =G27/$G$14 -> 0.077337664 | I27: =SUMIF(MVTO!$C$3:$C$72,"Imp_IR",MVTO!$I$3:$I$72) -> 51706.17 | J27: =I27/$I$14 -> 0.44825975 | K27: =SUMIF(MVTO!$C$3:$C$72,"Imp_IR",MVTO!$J$3:$J$72) -> 51706.17 | L27: =K27/$I$14 -> 0.44825975 | M27: =SUMIF(MVTO!$C$3:$C$72,"Imp_IR",MVTO!$K$3:$K$72) -> 51706.17 | N27: =M27/$I$14 -> 0.44825975 | O27: =SUMIF(MVTO!$C$3:$C$72,"Imp_IR",MVTO!$L$3:$L$72) -> 52473.69 | P27: =O27/$I$14 -> 0.45491366 | Q27: =SUMIF(MVTO!$C$3:$C$72,"Imp_IR",MVTO!$M$3:$M$72) -> 0 | R27: =Q27/$G$14 -> 0 | S27: =SUMIF(MVTO!$C$3:$C$72,"Imp_IR",MVTO!$N$3:$N$72) -> 0 | T27: =S27/$G$14 -> 0 | U27: =SUMIF(MVTO!$C$3:$C$72,"Imp_IR",MVTO!$O$3:$O$72) -> 0 | V27: =U27/$G$14 -> 0 | W27: =SUMIF(MVTO!$C$3:$C$72,"Imp_IR",MVTO!$P$3:$P$72) -> 0 | X27: =W27/$G$14 -> 0 | Y27: =SUMIF(MVTO!$C$3:$C$72,"Imp_IR",MVTO!$Q$3:$Q$72) -> 0 | Z27: =Y27/$C$14 -> 0 | AA27: =C27+E27+G27+I27+K27+M27+O27+Q27+S27+U27+W27+Y27 -> 375673.08 | AB27: =AA27/$AA$14 -> 0.1015879
B28: Lucro líquido | C28: =C25-C27+C26 -> 9304.9 | E28: =E25+E26-E27 -> 1252438.6 | G28: =G25+G26-G27 -> 579480.17 | I28: =I25+I26-I27 -> -21288.61 | K28: =K25+K26-K27 -> 254645.42 | M28: =M25+M26-M27 -> 300903.01 | O28: =O25+O26-O27 -> 296039.51 | Q28: =Q25+Q26-Q27 -> 0 | S28: =S25+S26-S27 -> 0 | U28: =U25+U26-U27 -> 0 | W28: =W25+W26-W27 -> 0 | Y28: =Y25+Y26-Y27 -> 0 | AA28: =C28+E28+G28+I28+K28+M28+O28+Q28+S28+U28+W28+Y28 -> 2671523
B29: PgtoEmpréstimos | C29: =SUMIF(MVTO!$C$3:$C$72,"Empréstimo",MVTO!$F$3:$F$72) -> 36969.98 | D29: =C29/$C$14 -> 0.25370154 | E29: =SUMIF(MVTO!$C$3:$C$72,"Empréstimo",MVTO!$G$3:$G$72) -> 36969.98 | F29: =E29/$E$14 -> 0.02577612 | G29: =SUMIF(MVTO!$C$3:$C$72,"Empréstimo",MVTO!$H$3:$H$72) -> 36969.98 | H29: =G29/$G$14 -> 0.051032073 | I29: =SUMIF(MVTO!$C$3:$C$72,"Empréstimo",MVTO!$I$3:$I$72) -> 36969.98 | J29: =I29/$I$14 -> 0.32050631 | K29: =SUMIF(MVTO!$C$3:$C$72,"Empréstimo",MVTO!$J$3:$J$72) -> 36969.98 | L29: =K29/$I$14 -> 0.32050631 | M29: =SUMIF(MVTO!$C$3:$C$72,"Empréstimo",MVTO!$K$3:$K$72) -> 36969.98 | N29: =M29/$I$14 -> 0.32050631 | O29: =SUMIF(MVTO!$C$3:$C$72,"Empréstimo",MVTO!$L$3:$L$72) -> 36969.98 | P29: =O29/$I$14 -> 0.32050631 | Q29: =SUMIF(MVTO!$C$3:$C$72,"Empréstimo",MVTO!$M$3:$M$72) -> 0 | R29: =Q29/$G$14 -> 0 | S29: =SUMIF(MVTO!$C$3:$C$72,"Empréstimo",MVTO!$N$3:$N$72) -> 0 | T29: =S29/$G$14 -> 0 | U29: =SUMIF(MVTO!$C$3:$C$72,"Empréstimo",MVTO!$O$3:$O$72) -> 0 | V29: =U29/$G$14 -> 0 | W29: =SUMIF(MVTO!$C$3:$C$72,"Empréstimo",MVTO!$P$3:$P$72) -> 0 | X29: =W29/$G$14 -> 0 | Y29: =SUMIF(MVTO!$C$3:$C$72,"Empréstimo",MVTO!$Q$3:$Q$72) -> 0 | Z29: =Y29/$C$14 -> 0 | AA29: =C29+E29+G29+I29+K29+M29+O29+Q29+S29+U29+W29+Y29 -> 258789.86 | AB29: =AA29/$AA$14 -> 0.069980841
B30: Envio a Ligadas | C30: =SUMIF(MVTO!$C$3:$C$72,"Ligadas_S",MVTO!$F$3:$F$72) -> 0 | D30: =C30/$C$14 -> 0 | E30: =SUMIF(MVTO!$C$3:$C$72,"Ligadas_S",MVTO!$G$3:$G$72) -> 0 | F30: =E30/$E$14 -> 0 | G30: =SUMIF(MVTO!$C$3:$C$72,"Ligadas_S",MVTO!$H$3:$H$72) -> 0 | H30: =G30/$G$14 -> 0 | I30: =SUMIF(MVTO!$C$3:$C$72,"Ligadas_S",MVTO!$I$3:$I$72) -> 64958 | J30: =I30/$I$14 -> 0.56314472 | K30: =SUMIF(MVTO!$C$3:$C$72,"Ligadas_S",MVTO!$J$3:$J$72) -> 1718.36 | L30: =K30/$I$14 -> 0.014897093 | M30: =SUMIF(MVTO!$C$3:$C$72,"Ligadas_S",MVTO!$K$3:$K$72) -> 2949.85 | N30: =M30/$I$14 -> 0.025573331 | O30: =SUMIF(MVTO!$C$3:$C$72,"Ligadas_S",MVTO!$L$3:$L$72) -> 8538.8 | P30: =O30/$I$14 -> 0.074025988 | Q30: =SUMIF(MVTO!$C$3:$C$72,"Ligadas_S",MVTO!$M$3:$M$72) -> 0 | R30: =Q30/$G$14 -> 0 | S30: =SUMIF(MVTO!$C$3:$C$72,"Ligadas_S",MVTO!$N$3:$N$72) -> 0 | T30: =S30/$G$14 -> 0 | U30: =SUMIF(MVTO!$C$3:$C$72,"Ligadas_S",MVTO!$O$3:$O$72) -> 0 | V30: =U30/$G$14 -> 0 | W30: =SUMIF(MVTO!$C$3:$C$72,"Ligadas_S",MVTO!$P$3:$P$72) -> 0 | X30: =W30/$G$14 -> 0 | Y30: =SUMIF(MVTO!$C$3:$C$72,"Ligadas_S",MVTO!$Q$3:$Q$72) -> 0 | Z30: =Y30/$C$14 -> 0 | AA30: =C30+E30+G30+I30+K30+M30+O30+Q30+S30+U30+W30+Y30 -> 78165.01 | AB30: =AA30/$AA$14 -> 0.021137046
B31: Invest/imobilizado | C31: =SUMIF(MVTO!$C$3:$C$72,"imobilizado",MVTO!$F$3:$F$72) -> 0 | D31: =C31/$C$14 -> 0 | E31: =SUMIF(MVTO!$C$3:$C$72,"Imobilizado",MVTO!$G$3:$G$72) -> 738529.3 | F31: =E31/$E$14 -> 0.51491561 | G31: =SUMIF(MVTO!$C$3:$C$72,"Imobilizado",MVTO!$H$3:$H$72) -> 71960.51 | H31: =G31/$G$14 -> 0.099331782 | I31: =SUMIF(MVTO!$C$3:$C$72,"Imobilizado",MVTO!$I$3:$I$72) -> 89270.36 | J31: =I31/$I$14 -> 0.77391748 | K31: =SUMIF(MVTO!$C$3:$C$72,"Imobilizado",MVTO!$J$3:$J$72) -> 170256.26 | L31: =K31/$I$14 -> 1.4760139 | M31: =SUMIF(MVTO!$C$3:$C$72,"Imobilizado",MVTO!$K$3:$K$72) -> 103527.88 | N31: =M31/$I$14 -> 0.89752115 | O31: =SUMIF(MVTO!$C$3:$C$72,"Imobilizado",MVTO!$L$3:$L$72) -> 86668.64 | P31: =O31/$I$14 -> 0.75136222 | Q31: =SUMIF(MVTO!$C$3:$C$72,"Imobilizado",MVTO!$M$3:$M$72) -> 0 | R31: =Q31/$G$14 -> 0 | S31: =SUMIF(MVTO!$C$3:$C$72,"Imobilizado",MVTO!$N$3:$N$72) -> 0 | T31: =S31/$G$14 -> 0 | U31: =SUMIF(MVTO!$C$3:$C$72,"Imobilizado",MVTO!$O$3:$O$72) -> 0 | V31: =U31/$G$14 -> 0 | W31: =SUMIF(MVTO!$C$3:$C$72,"Imobilizado",MVTO!$P$3:$P$72) -> 0 | X31: =W31/$G$14 -> 0 | Y31: =SUMIF(MVTO!$C$3:$C$72,"Imobilizado",MVTO!$Q$3:$Q$72) -> 0 | Z31: =Y31/$C$14 -> 0 | AA31: =C31+E31+G31+I31+K31+M31+O31+Q31+S31+U31+W31+Y31 -> 1260212.9 | AB31: =AA31/$AA$14 -> 0.34078136
B32: Entrada de Recursos | C32: =SUMIF(MVTO!$C$3:$C$72,"imobilizado",MVTO!$F$3:$F$72) -> 0 | D32: =C32/$C$14 -> 0 | E32: =SUMIF(MVTO!$C$3:$C$72,"Ligadas_E",MVTO!$G$3:$G$72)+SUMIF(MVTO!$C$3:$C$72,"Recursos_E",MVTO!$G$3:$G$72) -> 0 | F32: =E32/$E$14 -> 0 | G32: =SUMIF(MVTO!$C$3:$C$72,"Ligadas_E",MVTO!$H$3:$H$72) -> 0 | H32: =G32/$G$14 -> 0 | I32: =SUMIF(MVTO!$C$3:$C$72,"Ligadas_E",MVTO!$I$3:$I$72) -> 0 | J32: =I32/$I$14 -> 0 | K32: =SUMIF(MVTO!$C$3:$C$72,"Ligadas_E",MVTO!$J$3:$J$72) -> 33958 | L32: =K32/$I$14 -> 0.29439435 | M32: =SUMIF(MVTO!$C$3:$C$72,"Ligadas_E",MVTO!$K$3:$K$72) -> 13456.21 | N32: =M32/$I$14 -> 0.11665682 | O32: =SUMIF(MVTO!$C$3:$C$72,"Ligadas_E",MVTO!$L$3:$L$72) -> 0 | P32: =SUMIF(MVTO!$C$3:$C$72,"Ligadas_E",MVTO!$L$3:$L$72) -> 0 | Q32: =SUMIF(MVTO!$C$3:$C$72,"Ligadas_E",MVTO!$M$3:$M$72) -> 0 | R32: =Q32/$G$14 -> 0 | S32: =SUMIF(MVTO!$C$3:$C$72,"Ligadas_E",MVTO!$N$3:$N$72) -> 0 | T32: =S32/$G$14 -> 0 | U32: =SUMIF(MVTO!$C$3:$C$72,"Ligadas_E",MVTO!$O$3:$O$72) -> 0 | V32: =U32/$G$14 -> 0 | W32: =SUMIF(MVTO!$C$3:$C$72,"Ligadas_E",MVTO!$P$3:$P$72) -> 0 | X32: =W32/$G$14 -> 0 | Y32: =SUMIF(MVTO!$C$3:$C$72,"Ligadas_E",MVTO!$Q$3:$Q$72) -> 0 | Z32: =Y32/$C$14 -> 0 | AA32: =C32+E32+G32+I32+K32+M32+O32+Q32+S32+U32+W32+Y32 -> 47414.21 | AB32: =AA32/$AA$14 -> 0.012821547
B33: Resultado Caixa 1 | C33: =C28-C29-C30-C31+C32 -> -27665.08 | D33: =C33/$C$14 -> -0.18984791 | E33: =E28-E29-E30-E31+E32 -> 476939.36 | F33: =E33/$E$14 -> 0.33253051 | G33: =G28-G29-G30-G31+G32 -> 470549.68 | H33: =G33/$G$14 -> 0.64953039 | I33: =I28-I29-I30-I31+I32 -> -212486.95 | J33: =I33/$I$14 -> -1.8421273 | K33: =K28-K29-K30-K31+K32 -> 79658.82 | L33: =K33/$I$14 -> 0.69059152 | M33: =M28-M29-M30-M31+M32 -> 170911.51 | N33: =M33/$I$14 -> 1.4816945 | O33: =O28-O29-O30-O31+O32 -> 163862.09 | P33: =O33/$I$14 -> 1.4205805 | Q33: =Q28-Q29-Q30-Q31+Q32 -> 0 | R33: =Q33/$G$14 -> 0 | S33: =S28-S29-S30-S31+S32 -> 0 | T33: =S33/$G$14 -> 0 | U33: =U28-U29-U30-U31+U32 -> 0 | V33: =U33/$G$14 -> 0 | W33: =W28-W29-W30-W31+W32 -> 0 | X33: =W33/$G$14 -> 0 | Y33: =Y28-Y29-Y30-Y31+Y32 -> 0 | Z33: =Y33/$C$14 -> 0 | AA33: =C33+E33+G33+I33+K33+M33+O33+Q33+S33+U33+W33+Y33 -> 1121769.4 | AB33: =AA33/$AA$14 -> 0.30334406
B34: Total de Sócios | C34: =SUM(C35:C38) -> 154723.57 | D34: =C34/$C$14 -> 1.0617698 | E34: =SUM(E35:E38) -> 144347.06 | F34: =E34/$E$14 -> 0.10064131 | G34: =SUM(G35:G38) -> 153061.82 | H34: =G34/$G$14 -> 0.21128121 | I34: =SUM(I35:I38) -> 210317.77 | J34: =I34/$I$14 -> 1.8233219 | K34: =SUM(K35:K38) -> 188092.63 | L34: =K34/$I$14 -> 1.630644 | M34: =SUM(M35:M38) -> 240937.51 | N34: =M34/$I$14 -> 2.0887756 | O34: =SUM(O35:O38) -> 249673.47 | P34: =O34/$I$14 -> 2.1645109 | Q34: =SUM(Q35:Q38) -> 0 | R34: =Q34/$G$14 -> 0 | S34: =SUM(S35:S38) -> 0 | T34: =S34/$G$14 -> 0 | U34: =SUM(U35:U38) -> 0 | V34: =U34/$G$14 -> 0 | W34: =SUM(W35:W38) -> 0 | X34: =W34/$G$14 -> 0 | Y34: =SUM(Y35:Y38) -> 0 | Z34: =Y34/$C$14 -> 0 | AA34: =C34+E34+G34+I34+K34+M34+O34+Q34+S34+U34+W34+Y34 -> 1341153.8 | AB34: =AA34/$AA$14 -> 0.36266905
B35: Sócio_Diego | C35: =SUMIF(MVTO!$C$3:$C$72,"Sócio_Diego",MVTO!$F$3:$F$72) -> 27593.81 | D35: =C35/$C$14 -> 0.18935883 | E35: =SUMIF(MVTO!$C$3:$C$72,"Sócio_Diego",MVTO!$G$3:$G$72) -> 32612.75 | F35: =E35/$E$14 -> 0.022738183 | G35: =SUMIF(MVTO!$C$3:$C$72,"Sócio_Diego",MVTO!$H$3:$H$72) -> 32502.67 | H35: =G35/$G$14 -> 0.044865554 | I35: =SUMIF(MVTO!$C$3:$C$72,"Sócio_Diego",MVTO!$I$3:$I$72) -> 38690.86 | J35: =I35/$I$14 -> 0.33542525 | K35: =SUMIF(MVTO!$C$3:$C$72,"Sócio_Diego",MVTO!$J$3:$J$72) -> 45261.76 | L35: =K35/$I$14 -> 0.39239079 | M35: =SUMIF(MVTO!$C$3:$C$72,"Sócio_Diego",MVTO!$K$3:$K$72) -> 48231.95 | N35: =M35/$I$14 -> 0.41814046 | O35: =SUMIF(MVTO!$C$3:$C$72,"Sócio_Diego",MVTO!$L$3:$L$72) -> 34675.74 | P35: =O35/$I$14 -> 0.3006167 | Q35: =SUMIF(MVTO!$C$3:$C$72,"Sócio_Diego",MVTO!$M$3:$M$72) -> 0 | R35: =Q35/$G$14 -> 0 | S35: =SUMIF(MVTO!$C$3:$C$72,"Sócio_Diego",MVTO!$N$3:$N$72) -> 0 | T35: =S35/$G$14 -> 0 | U35: =SUMIF(MVTO!$C$3:$C$72,"Sócio_Diego",MVTO!$O$3:$O$72) -> 0 | V35: =U35/$G$14 -> 0 | W35: =SUMIF(MVTO!$C$3:$C$72,"Sócio_Diego",MVTO!$P$3:$P$72) -> 0 | X35: =W35/$G$14 -> 0 | Y35: =SUMIF(MVTO!$C$3:$C$72,"Sócio_Diego",MVTO!$Q$3:$Q$72) -> 0 | Z35: =Y35/$C$14 -> 0 | AA35: =C35+E35+G35+I35+K35+M35+O35+Q35+S35+U35+W35+Y35 -> 259569.54 | AB35: =AA35/$AA$14 -> 0.070191678
B36: Sócio_Thiago | C36: =SUMIF(MVTO!$C$3:$C$72,"Sócio_Thiago",MVTO!$F$3:$F$72) -> 46201.36 | D36: =C36/$C$14 -> 0.31705065 | E36: =SUMIF(MVTO!$C$3:$C$72,"Sócio_Thiago",MVTO!$G$3:$G$72) -> 31008.67 | F36: =E36/$E$14 -> 0.02161979 | G36: =SUMIF(MVTO!$C$3:$C$72,"Sócio_Thiago",MVTO!$H$3:$H$72) -> 36008.64 | H36: =G36/$G$14 -> 0.049705073 | I36: =SUMIF(MVTO!$C$3:$C$72,"Sócio_Thiago",MVTO!$I$3:$I$72) -> 41008.64 | J36: =I36/$I$14 -> 0.35551894 | K36: =SUMIF(MVTO!$C$3:$C$72,"Sócio_Thiago",MVTO!$J$3:$J$72) -> 46295.6 | L36: =K36/$I$14 -> 0.40135353 | M36: =SUMIF(MVTO!$C$3:$C$72,"Sócio_Thiago",MVTO!$K$3:$K$72) -> 92249.19 | N36: =M36/$I$14 -> 0.79974205 | O36: =SUMIF(MVTO!$C$3:$C$72,"Sócio_Thiago",MVTO!$L$3:$L$72) -> 64470.93 | P36: =O36/$I$14 -> 0.55892213 | Q36: =SUMIF(MVTO!$C$3:$C$72,"Sócio_Thiago",MVTO!$M$3:$M$72) -> 0 | R36: =Q36/$G$14 -> 0 | S36: =SUMIF(MVTO!$C$3:$C$72,"Sócio_Thiago",MVTO!$N$3:$N$72) -> 0 | T36: =S36/$G$14 -> 0 | U36: =SUMIF(MVTO!$C$3:$C$72,"Sócio_Thiago",MVTO!$O$3:$O$72) -> 0 | V36: =U36/$G$14 -> 0 | W36: =SUMIF(MVTO!$C$3:$C$72,"Sócio_Thiago",MVTO!$P$3:$P$72) -> 0 | X36: =W36/$G$14 -> 0 | Y36: =SUMIF(MVTO!$C$3:$C$72,"Sócio_Thiago",MVTO!$Q$3:$Q$72) -> 0 | Z36: =Y36/$C$14 -> 0 | AA36: =C36+E36+G36+I36+K36+M36+O36+Q36+S36+U36+W36+Y36 -> 357243.03 | AB36: =AA36/$AA$14 -> 0.096604123
B37: Sócio_Pátricia | C37: =SUMIF(MVTO!$C$3:$C$72,"Sócio_Pátricia",MVTO!$F$3:$F$72) -> 42328.4 | D37: =C37/$C$14 -> 0.29047298 | E37: =SUMIF(MVTO!$C$3:$C$72,"Sócio_Pátricia",MVTO!$G$3:$G$72) -> 32152.64 | F37: =E37/$E$14 -> 0.022417386 | G37: =SUMIF(MVTO!$C$3:$C$72,"Sócio_Pátricia",MVTO!$H$3:$H$72) -> 31008.67 | H37: =G37/$G$14 -> 0.042803288 | I37: =SUMIF(MVTO!$C$3:$C$72,"Sócio_Pátricia",MVTO!$I$3:$I$72) -> 46038.11 | J37: =I37/$I$14 -> 0.39912126 | K37: =SUMIF(MVTO!$C$3:$C$72,"Sócio_Pátricia",MVTO!$J$3:$J$72) -> 46008.67 | L37: =K37/$I$14 -> 0.39886603 | M37: =SUMIF(MVTO!$C$3:$C$72,"Sócio_Pátricia",MVTO!$K$3:$K$72) -> 46052.85 | N37: =M37/$I$14 -> 0.39924904 | O37: =SUMIF(MVTO!$C$3:$C$72,"Sócio_Pátricia",MVTO!$L$3:$L$72) -> 37200 | P37: =O37/$I$14 -> 0.32250044 | Q37: =SUMIF(MVTO!$C$3:$C$72,"Sócio_Pátricia",MVTO!$M$3:$M$72) -> 0 | R37: =Q37/$G$14 -> 0 | S37: =SUMIF(MVTO!$C$3:$C$72,"Sócio_Pátricia",MVTO!$N$3:$N$72) -> 0 | T37: =S37/$G$14 -> 0 | U37: =SUMIF(MVTO!$C$3:$C$72,"Sócio_Pátricia",MVTO!$O$3:$O$72) -> 0 | V37: =U37/$G$14 -> 0 | W37: =SUMIF(MVTO!$C$3:$C$72,"Sócio_Pátricia",MVTO!$P$3:$P$72) -> 0 | X37: =W37/$G$14 -> 0 | Y37: =SUMIF(MVTO!$C$3:$C$72,"Sócio_Pátricia",MVTO!$Q$3:$Q$72) -> 0 | Z37: =Y37/$C$14 -> 0 | AA37: =C37+E37+G37+I37+K37+M37+O37+Q37+S37+U37+W37+Y37 -> 280789.34 | AB37: =AA37/$AA$14 -> 0.075929845
B38: Sócio_Tubertino | C38: =SUMIF(MVTO!$C$3:$C$72,"Sócio_Tubertino",MVTO!$F$3:$F$72) -> 38600 | D38: =C38/$C$14 -> 0.26488734 | E38: =SUMIF(MVTO!$C$3:$C$72,"Sócio_Tubertino",MVTO!$G$3:$G$72) -> 48573 | F38: =E38/$E$14 -> 0.03386595 | G38: =SUMIF(MVTO!$C$3:$C$72,"Sócio_Tubertino",MVTO!$H$3:$H$72) -> 53541.84 | H38: =G38/$G$14 -> 0.073907291 | I38: =SUMIF(MVTO!$C$3:$C$72,"Sócio_Tubertino",MVTO!$I$3:$I$72) -> 84580.16 | J38: =I38/$I$14 -> 0.73325642 | K38: =SUMIF(MVTO!$C$3:$C$72,"Sócio_Tubertino",MVTO!$J$3:$J$72) -> 50526.6 | L38: =K38/$I$14 -> 0.43803362 | M38: =SUMIF(MVTO!$C$3:$C$72,"Sócio_Tubertino",MVTO!$K$3:$K$72) -> 54403.52 | N38: =M38/$I$14 -> 0.47164406 | O38: =SUMIF(MVTO!$C$3:$C$72,"Sócio_Tubertino",MVTO!$L$3:$L$72) -> 113326.8 | P38: =O38/$I$14 -> 0.98247158 | Q38: =SUMIF(MVTO!$C$3:$C$72,"Sócio_Tubertino",MVTO!$M$3:$M$72) -> 0 | R38: =Q38/$G$14 -> 0 | S38: =SUMIF(MVTO!$C$3:$C$72,"Sócio_Tubertino",MVTO!$N$3:$N$72) -> 0 | T38: =S38/$G$14 -> 0 | U38: =SUMIF(MVTO!$C$3:$C$72,"Sócio_Tubertino",MVTO!$O$3:$O$72) -> 0 | V38: =U38/$G$14 -> 0 | W38: =SUMIF(MVTO!$C$3:$C$72,"Sócio_Tubertino",MVTO!$P$3:$P$72) -> 0 | X38: =W38/$G$14 -> 0 | Y38: =SUMIF(MVTO!$C$3:$C$72,"Sócio_Tubertino",MVTO!$Q$3:$Q$72) -> 0 | Z38: =Y38/$C$14 -> 0 | AA38: =C38+E38+G38+I38+K38+M38+O38+Q38+S38+U38+W38+Y38 -> 443551.92 | AB38: =AA38/$AA$14 -> 0.1199434
B39: Var Final Caixa | C39: =C33-C34 -> -182388.65 | E39: =E33-E34 -> 332592.3 | G39: =G33-G34 -> 317487.86 | I39: =I33-I34 -> -422804.72 | K39: =K33-K34 -> -108433.81 | M39: =M33-M34 -> -70026 | O39: =O33-O34 -> -85811.38 | Q39: =Q33-Q34 -> 0 | S39: =S33-S34 -> 0 | U39: =U33-U34 -> 0 | W39: =W33-W34 -> 0 | Y39: =Y33-Y34 -> 0 | AA39: =C39+E39+G39+I39+K39+M39+O39+Q39+S39+U39+W39+Y39 -> -219384.4
B42: SALDO INICIAL | C42: =MVTO!F76 -> 233299.47 | E42: =MVTO!G76 -> 50910.82 | G42: =MVTO!H76 -> 383503.11 | I42: =MVTO!I76 -> 700990.97 | K42: =MVTO!J76 -> 278186.25 | M42: =MVTO!K76 -> 169752.44 | O42: =MVTO!L76 -> 99726.44 | Q42: =MVTO!M76 -> 0 | S42: =MVTO!N76 -> 0 | U42: =MVTO!O76 -> 0 | W42: =MVTO!P76 -> 0 | Y42: =MVTO!Q76 -> 0 | AA42: =C42 -> 233299.47
B43: SALDO FINAL | C43: =MVTO!F77 -> 50910.82 | E43: =MVTO!G77 -> 383503.11 | G43: =MVTO!H77 -> 700990.97 | I43: =MVTO!I77 -> 278186.25 | K43: =MVTO!J77 -> 169752.44 | M43: =MVTO!K77 -> 99726.44 | O43: =MVTO!L77 -> 13915.06 | Q43: =MVTO!M77 -> 0 | S43: =MVTO!N77 -> 0 | U43: =MVTO!O77 -> 0 | W43: =MVTO!P77 -> 0 | Y43: =MVTO!Q77 -> 0 | AA43: =G43 -> 700990.97
C45: =C43-C42 -> -182388.65 | E45: =E43-E42 -> 332592.29 | G45: =G43-G42 -> 317487.86 | W45: =W42-W43 -> 0 | Y45: =Y42-Y43 -> 0 | AA45: =AA43-AA42 -> 467691.5
...

Sheet COMPARATIVO
B3: 2026
B4: DEMONSTRAÇÃO CAIXA / ECONÔMICO
C5: JANEIRO | E5: FEVEREIRO | G5: MARÇO | I5: ABRIL | K5: MAIO | M5: JUNHO | O5: JULHO | Q5: AGOSTO | S5: SETEMBRO | U5: OUTUBRO | W5: NOVEMBRO | Y5: DEZEMBRO | AA5: RESULTADO ANO
C6: CAIXA | D6: ECONÔMICO | E6: CAIXA | F6: ECONÔMICO | G6: CAIXA | H6: ECONÔMICO | I6: CAIXA | J6: ECONÔMICO | K6: CAIXA | L6: ECONÔMICO | M6: CAIXA | N6: ECONÔMICO | O6: CAIXA | P6: ECONÔMICO | Q6: CAIXA | R6: ECONÔMICO | S6: CAIXA | T6: ECONÔMICO | U6: CAIXA | V6: ECONÔMICO | W6: CAIXA | X6: ECONÔMICO | Y6: CAIXA | Z6: ECONÔMICO | AA6: CAIXA | AB6: ECONÔMICO
B7: Prestação de Serviço - Clientes | C7: =MVTO!F3 -> 19875.28 | E7: =MVTO!G3-MVTO!G25 -> 40161.63 | G7: =MVTO!H3 -> 38795.06 | I7: =MVTO!I3 -> 26231.38 | K7: =MVTO!J3 -> 51183.74 | M7: =MVTO!K3 -> 34086.27 | O7: =MVTO!L3 -> 40272.17 | Q7: =MVTO!M3 -> 0 | S7: =MVTO!N3 -> 0 | U7: =MVTO!O3 -> 0 | W7: =MVTO!P3 -> 0 | Y7: =MVTO!Q3 -> 0 | AA7: =MVTO!R3-MVTO!R25 -> 250605.53
B8: Prestação de Serviço - Und 01 | C8: =MVTO!F4 -> 25000 | E8: =MVTO!G4 -> 980250.35 | G8: =MVTO!H4 -> 60836.15 | I8: =MVTO!I4 -> 2177 | K8: =MVTO!J4 -> 220742.97 | M8: =MVTO!K4 -> 40000 | O8: =MVTO!L4 -> 20000 | Q8: =MVTO!M4 -> 0 | S8: =MVTO!N4 -> 0 | U8: =MVTO!O4 -> 0 | W8: =MVTO!P4 -> 0 | Y8: =MVTO!Q4 -> 0 | AA8: =MVTO!R4 -> 1349006.5
B9: Prestação de Serviço - Und 02 | C9: =MVTO!F5 -> 100847.05 | E9: =MVTO!G5 -> 140045.89 | G9: =MVTO!H5 -> 342469.87 | I9: =MVTO!I5 -> 12000 | K9: =MVTO!J5 -> 13425 | M9: =MVTO!K5 -> 233116.41 | O9: =MVTO!L5 -> 108332.31 | Q9: =MVTO!M5 -> 0 | S9: =MVTO!N5 -> 0 | U9: =MVTO!O5 -> 0 | W9: =MVTO!P5 -> 0 | Y9: =MVTO!Q5 -> 0 | AA9: =MVTO!R5 -> 950236.53
B10: Prestação de Serviço - Und 03 | C10: =MVTO!F6 -> 0 | E10: =MVTO!G6 -> 173814.62 | G10: =MVTO!H6 -> 182344.9 | I10: =MVTO!I6 -> 74940.3 | K10: =MVTO!J6 -> 12000 | M10: =MVTO!K6 -> 92193.49 | O10: =MVTO!L6 -> 162868.32 | Q10: =MVTO!M6 -> 0 | S10: =MVTO!N6 -> 0 | U10: =MVTO!O6 -> 0 | W10: =MVTO!P6 -> 0 | Y10: =MVTO!Q6 -> 0 | AA10: =MVTO!R6 -> 698161.63
B11: Prestação de Serviço - Und 04 | C11: =MVTO!F7 -> 0 | E11: =MVTO!G7 -> 100000 | G11: =MVTO!H7 -> 100000 | I11: =MVTO!I7 -> 0 | K11: =MVTO!J7 -> 100000 | M11: =MVTO!K7 -> 50000 | O11: =MVTO!L7 -> 100000 | Q11: =MVTO!M7 -> 0 | S11: =MVTO!N7 -> 0 | U11: =MVTO!O7 -> 0 | W11: =MVTO!P7 -> 0 | X11: =MVTO!Q7 -> 0 | Y11: =MVTO!Q7 -> 0 | Z11: =MVTO!S7 -> 0 | AA11: =MVTO!R7 -> 450000
B12: Serviços - Clientes | C12: =C7 -> 19875.28 | E12: =E7 -> 40161.63 | G12: =G7 -> 38795.06 | I12: =I7 -> 26231.38 | K12: =K7 -> 51183.74 | M12: =M7 -> 34086.27 | O12: =O7 -> 40272.17 | Q12: =Q7 -> 0 | S12: =S7 -> 0 | U12: =U7 -> 0 | W12: =W7 -> 0 | Y12: =Y7 -> 0 | AA12: =AA7 -> 250605.53
B13: Serviços - TJ | C13: =SUM(C8:C10) -> 125847.05 | E13: =SUM(E8:E11) -> 1394110.9 | G13: =SUM(G8:G11) -> 685650.92 | I13: =SUM(I8:I11) -> 89117.3 | K13: =SUM(K8:K11) -> 346167.97 | M13: =SUM(M8:M11) -> 415309.9 | O13: =SUM(O8:O11) -> 391200.63 | Q13: =SUM(Q8:Q11) -> 0 | S13: =SUM(S8:S11) -> 0 | U13: =SUM(U8:U11) -> 0 | W13: =SUM(W8:W11) -> 0 | Y13: =SUM(Y8:Y11) -> 0 | AA13: =SUM(AA8:AA11) -> 3447404.6
B14: Total Receitas Serviços | C14: =SUM(C12:C13) -> 145722.33 | E14: =SUM(E12:E13) -> 1434272.5 | G14: =SUM(G12:G13) -> 724445.98 | I14: =SUM(I12:I13) -> 115348.68 | K14: =SUM(K12:K13) -> 397351.71 | M14: =SUM(M12:M13) -> 449396.17 | O14: =SUM(O12:O13) -> 431472.8 | Q14: =SUM(Q12:Q13) -> 0 | S14: =SUM(S12:S13) -> 0 | U14: =SUM(U12:U13) -> 0 | W14: =SUM(W12:W13) -> 0 | Y14: =SUM(Y12:Y13) -> 0 | AA14: =SUM(AA12:AA13) -> 3698010.2
B15: Impostos S/ Serviços | C15: =SUMIF(MVTO!$C$3:$C$72,"Imp_Receita",MVTO!$F$3:$F$72) -> 20540.01 | E15: =SUMIF(MVTO!$C$3:$C$72,"Imp_Receita",MVTO!$G$3:$G$72) -> 18169.35 | G15: =SUMIF(MVTO!$C$3:$C$72,"Imp_Receita",MVTO!$H$3:$H$72) -> 17598.97 | I15: =SUMIF(MVTO!$C$3:$C$72,"Imp_Receita",MVTO!$I$3:$I$72) -> 18497.11 | K15: =SUMIF(MVTO!$C$3:$C$72,"Imp_Receita",MVTO!$J$3:$J$72) -> 18618.72 | M15: =SUMIF(MVTO!$C$3:$C$72,"Imp_Receita",MVTO!$K$3:$K$72) -> 18723.36 | O15: =SUMIF(MVTO!$C$3:$C$72,"Imp_Receita",MVTO!$L$3:$L$72) -> 17509.6 | Q15: =SUMIF(MVTO!$C$3:$C$72,"Imp_Receita",MVTO!$M$3:$M$72) -> 0 | S15: =SUMIF(MVTO!$C$3:$C$72,"Imp_Receita",MVTO!$N$3:$N$72) -> 0 | U15: =SUMIF(MVTO!$C$3:$C$72,"Imp_Receita",MVTO!$O$3:$O$72) -> 0 | W15: =SUMIF(MVTO!$C$3:$C$72,"Imp_Receita",MVTO!$P$3:$P$72) -> 0 | Y15: =SUMIF(MVTO!$C$3:$C$72,"Imp_Receita",MVTO!$Q$3:$Q$72) -> 0 | AA15: =SUMIF(MVTO!$C$3:$C$72,"Imp_Receita",MVTO!$R$3:$R$72) -> 129524.59
B16: Recuperação de Despesas | C16: =SUMIF(MVTO!$C$3:$C$72,"Rec_Despesa",MVTO!$F$3:$F$72) -> 0 | E16: =SUMIF(MVTO!$C$3:$C$72,"Rec_Despesa",MVTO!$G$3:$G$72) -> 0 | G16: =SUMIF(MVTO!$C$3:$C$72,"Rec_Despesa",MVTO!$H$3:$H$72) -> 0 | I16: =SUMIF(MVTO!$C$3:$C$72,"Rec_Despesa",MVTO!$I$3:$I$72) -> 0 | K16: =SUMIF(MVTO!$C$3:$C$72,"Rec_Despesa",MVTO!$J$3:$J$72) -> 0 | M16: =SUMIF(MVTO!$C$3:$C$72,"Rec_Despesa",MVTO!$K$3:$K$72) -> 0 | O16: =SUMIF(MVTO!$C$3:$C$72,"Rec_Despesa",MVTO!$L$3:$L$72) -> 0 | Q16: =SUMIF(MVTO!$C$3:$C$72,"Rec_Despesa",MVTO!$M$3:$M$72) -> 0 | S16: =SUMIF(MVTO!$C$3:$C$72,"Rec_Despesa",MVTO!$N$3:$N$72) -> 0 | U16: =SUMIF(MVTO!$C$3:$C$72,"Rec_Despesa",MVTO!$O$3:$O$72) -> 0 | W16: =SUMIF(MVTO!$C$3:$C$72,"Rec_Despesa",MVTO!$O$3:$O$72) -> 0 | Y16: =SUMIF(MVTO!$C$3:$C$72,"Rec_Despesa",MVTO!$Q$3:$Q$72) -> 0 | AA16: =SUMIF(MVTO!$C$3:$C$72,"Rec_Despesa",MVTO!$R$3:$R$72) -> 0
B17: Lucro Bruto | C17: =C14-C15+C16 -> 125182.32 | E17: =E14-E15+E16 -> 1416103.1 | G17: =G14-G15+G16 -> 706847.01 | I17: =I14-I15+I16 -> 96851.57 | K17: =K14-K15+K16 -> 378732.99 | M17: =M14-M15+M16 -> 430672.81 | O17: =O14-O15+O16 -> 413963.2 | Q17: =Q14-Q15+Q16 -> 0 | S17: =S14-S15+S16 -> 0 | U17: =U14-U15+U16 -> 0 | W17: =W14-W15+W16 -> 0 | Y17: =Y14-Y15+Y16 -> 0 | AA17: =AA14-AA15+AA16 -> 3568485.6
B18: Custos operacionais | C18: =SUM(C19:C24) -> 58258.9 | E18: =SUM(E19:E24) -> 93360.55 | G18: =SUM(G19:G24) -> 73693.08 | I18: =SUM(I19:I24) -> 64229.99 | K18: =SUM(K19:K24) -> 73113.22 | M18: =SUM(M19:M24) -> 76137.63 | O18: =SUM(O19:O24) -> 65424.67 | Q18: =SUM(Q19:Q24) -> 0 | S18: =SUM(S19:S24) -> 0 | U18: =SUM(U19:U24) -> 0 | W18: =SUM(W19:W24) -> 0 | Y18: =SUM(Y19:Y24) -> 0 | AA18: =SUM(AA19:AA24) -> 504218.04
B19: Alugueis | C19: =SUMIF(MVTO!$C$3:$C$72,"Aluguel",MVTO!$F$3:$F$72) -> 56764 | E19: =SUMIF(MVTO!$C$3:$C$72,"Aluguel",MVTO!$G$3:$G$72) -> 57185 | G19: =SUMIF(MVTO!$C$3:$C$72,"Aluguel",MVTO!$H$3:$H$72) -> 57185 | I19: =SUMIF(MVTO!$C$3:$C$72,"Aluguel",MVTO!$I$3:$I$72) -> 57185 | K19: =SUMIF(MVTO!$C$3:$C$72,"Aluguel",MVTO!$J$3:$J$72) -> 57251 | M19: =SUMIF(MVTO!$C$3:$C$72,"Aluguel",MVTO!$K$3:$K$72) -> 57251 | O19: =SUMIF(MVTO!$C$3:$C$72,"Aluguel",MVTO!$L$3:$L$72) -> 57251 | Q19: =SUMIF(MVTO!$C$3:$C$72,"Aluguel",MVTO!$M$3:$M$72) -> 0 | S19: =SUMIF(MVTO!$C$3:$C$72,"Aluguel",MVTO!$N$3:$N$72) -> 0 | U19: =SUMIF(MVTO!$C$3:$C$72,"Aluguel",MVTO!$O$3:$O$72) -> 0 | W19: =SUMIF(MVTO!$C$3:$C$72,"Aluguel",MVTO!$P$3:$P$72) -> 0 | Y19: =SUMIF(MVTO!$C$3:$C$72,"Aluguel",MVTO!$Q$3:$Q$72) -> 0 | AA19: =SUMIF(MVTO!$C$3:$C$72,"Aluguel",MVTO!$R$3:$R$72) -> 400072
B20: Tributos | C20: =SUMIF(MVTO!$C$3:$C$72,"Tributário",MVTO!$F$3:$F$72) -> 307.8 | E20: =SUMIF(MVTO!$C$3:$C$72,"Tributário",MVTO!$G$3:$G$72) -> 14959.05 | G20: =SUMIF(MVTO!$C$3:$C$72,"Tributário",MVTO!$H$3:$H$72) -> 8131.25 | I20: =SUMIF(MVTO!$C$3:$C$72,"Tributário",MVTO!$I$3:$I$72) -> 56.5 | K20: =SUMIF(MVTO!$C$3:$C$72,"Tributário",MVTO!$J$3:$J$72) -> 10741.77 | M20: =SUMIF(MVTO!$C$3:$C$72,"Tributário",MVTO!$K$3:$K$72) -> 11410.06 | O20: =SUMIF(MVTO!$C$3:$C$72,"Tributário",MVTO!$L$3:$L$72) -> 2666.79 | Q20: =SUMIF(MVTO!$C$3:$C$72,"Tributário",MVTO!$M$3:$M$72) -> 0 | S20: =SUMIF(MVTO!$C$3:$C$72,"Tributário",MVTO!$N$3:$N$72) -> 0 | U20: =SUMIF(MVTO!$C$3:$C$72,"Tributário",MVTO!$O$3:$O$72) -> 0 | W20: =SUMIF(MVTO!$C$3:$C$72,"Tributário",MVTO!$P$3:$P$72) -> 0 | Y20: =SUMIF(MVTO!$C$3:$C$72,"Tributário",MVTO!$Q$3:$Q$72) -> 0 | AA20: =SUMIF(MVTO!$C$3:$C$72,"Tributário",MVTO!$R$3:$R$72) -> 48273.22
B21: Água e Esgotos | C21: =SUMIF(MVTO!$C$3:$C$72,"Água",MVTO!$F$3:$F$72) -> 900.1 | E21: =SUMIF(MVTO!$C$3:$C$72,"Água",MVTO!$G$3:$G$72) -> 1447.43 | G21: =SUMIF(MVTO!$C$3:$C$72,"Água",MVTO!$H$3:$H$72) -> 984.75 | I21: =SUMIF(MVTO!$C$3:$C$72,"Água",MVTO!$I$3:$I$72) -> 1022.8 | K21: =SUMIF(MVTO!$C$3:$C$72,"Água",MVTO!$J$3:$J$72) -> 767.55 | M21: =SUMIF(MVTO!$C$3:$C$72,"Água",MVTO!$K$3:$K$72) -> 1670.95 | O21: =SUMIF(MVTO!$C$3:$C$72,"Água",MVTO!$L$3:$L$72) -> 1314.24 | Q21: =SUMIF(MVTO!$C$3:$C$72,"Água",MVTO!$M$3:$M$72) -> 0 | S21: =SUMIF(MVTO!$C$3:$C$72,"Água",MVTO!$N$3:$N$72) -> 0 | U21: =SUMIF(MVTO!$C$3:$C$72,"Água",MVTO!$O$3:$O$72) -> 0 | W21: =SUMIF(MVTO!$C$3:$C$72,"Água",MVTO!$P$3:$P$72) -> 0 | Y21: =SUMIF(MVTO!$C$3:$C$72,"Água",MVTO!$Q$3:$Q$72) -> 0 | AA21: =SUMIF(MVTO!$C$3:$C$72,"Água",MVTO!$R$3:$R$72) -> 8107.82
B22: Depósito Judicial | C22: =SUMIF(MVTO!$C$3:$C$72,"Dep_Judicial",MVTO!$F$3:$F$72) -> 0 | E22: =SUMIF(MVTO!$C$3:$C$72,"Dep_Judicial",MVTO!$G$3:$G$72) -> 0 | G22: =SUMIF(MVTO!$C$3:$C$72,"Dep_Judicial",MVTO!$H$3:$H$72) -> 0 | I22: =SUMIF(MVTO!$C$3:$C$72,"Dep_Judicial",MVTO!$I$3:$I$72) -> 0 | K22: =SUMIF(MVTO!$C$3:$C$72,"Dep_Judicial",MVTO!$J$3:$J$72) -> 0 | M22: =SUMIF(MVTO!$C$3:$C$72,"Dep_Judicial",MVTO!$K$3:$K$72) -> 0 | O22: =SUMIF(MVTO!$C$3:$C$72,"Dep_Judicial",MVTO!$L$3:$L$72) -> 0 | Q22: =SUMIF(MVTO!$C$3:$C$72,"Dep_Judicial",MVTO!$M$3:$M$72) -> 0 | S22: =SUMIF(MVTO!$C$3:$C$72,"Dep_Judicial",MVTO!$N$3:$N$72) -> 0 | U22: =SUMIF(MVTO!$C$3:$C$72,"Dep_Judicial",MVTO!$O$3:$O$72) -> 0 | W22: =SUMIF(MVTO!$C$3:$C$72,"Dep_Judicial",MVTO!$P$3:$P$72) -> 0 | Y22: =SUMIF(MVTO!$C$3:$C$72,"Dep_Judicial",MVTO!$Q$3:$Q$72) -> 0 | AA22: =SUMIF(MVTO!$C$3:$C$72,"Dep_Judicial",MVTO!$R$3:$R$72) -> 0
B23: Manutenção Imóvel | C23: =SUMIF(MVTO!$C$3:$C$72,"Desp_imovel",MVTO!$F$3:$F$72) -> 287 | E23: =SUMIF(MVTO!$C$3:$C$72,"Desp_imovel",MVTO!$G$3:$G$72) -> 19769.07 | G23: =SUMIF(MVTO!$C$3:$C$72,"Desp_imovel",MVTO!$H$3:$H$72) -> 7392.08 | I23: =SUMIF(MVTO!$C$3:$C$72,"Desp_imovel",MVTO!$I$3:$I$72) -> 5965.69 | K23: =SUMIF(MVTO!$C$3:$C$72,"Desp_imovel",MVTO!$J$3:$J$72) -> 4352.9 | M23: =SUMIF(MVTO!$C$3:$C$72,"Desp_imovel",MVTO!$K$3:$K$72) -> 5805.62 | O23: =SUMIF(MVTO!$C$3:$C$72,"Desp_imovel",MVTO!$L$3:$L$72) -> 4192.64 | Q23: =SUMIF(MVTO!$C$3:$C$72,"Desp_imovel",MVTO!$M$3:$M$72) -> 0 | S23: =SUMIF(MVTO!$C$3:$C$72,"Desp_imovel",MVTO!$N$3:$N$72) -> 0 | U23: =SUMIF(MVTO!$C$3:$C$72,"Desp_imovel",MVTO!$O$3:$O$72) -> 0 | W23: =SUMIF(MVTO!$C$3:$C$72,"Desp_imovel",MVTO!$P$3:$P$72) -> 0 | Y23: =SUMIF(MVTO!$C$3:$C$72,"Desp_imovel",MVTO!$Q$3:$Q$72) -> 0 | AA23: =SUMIF(MVTO!$C$3:$C$72,"Desp_imovel",MVTO!$R$3:$R$72) -> 47765
B24: Pessoal | C24: =SUMIF(MVTO!$C$3:$C$72,"Pessoal",MVTO!$F$3:$F$72) -> 0 | E24: =SUMIF(MVTO!$C$3:$C$72,"Pessoal",MVTO!$G$3:$G$72) -> 0 | G24: =SUMIF(MVTO!$C$3:$C$72,"Pessoal",MVTO!$H$3:$H$72) -> 0 | I24: =SUMIF(MVTO!$C$3:$C$72,"Pessoal",MVTO!$I$3:$I$72) -> 0 | K24: =SUMIF(MVTO!$C$3:$C$72,"Pessoal",MVTO!$J$3:$J$72) -> 0 | M24: =SUMIF(MVTO!$C$3:$C$72,"Pessoal",MVTO!$K$3:$K$72) -> 0 | O24: =SUMIF(MVTO!$C$3:$C$72,"Pessoal",MVTO!$L$3:$L$72) -> 0 | Q24: =SUMIF(MVTO!$C$3:$C$72,"Pessoal",MVTO!$M$3:$M$72) -> 0 | S24: =SUMIF(MVTO!$C$3:$C$72,"Pessoal",MVTO!$N$3:$N$72) -> 0 | U24: =SUMIF(MVTO!$C$3:$C$72,"Pessoal",MVTO!$O$3:$O$72) -> 0 | W24: =SUMIF(MVTO!$C$3:$C$72,"Pessoal",MVTO!$P$3:$P$72) -> 0 | Y24: =SUMIF(MVTO!$C$3:$C$72,"Pessoal",MVTO!$Q$3:$Q$72) -> 0 | AA24: =SUMIF(MVTO!$C$3:$C$72,"Pessoal",MVTO!$R$3:$R$72) -> 0
B25: Lucro das operações | C25: =C17-C18 -> 66923.42 | E25: =E17-E18 -> 1322742.6 | G25: =G17-G18 -> 633153.93 | I25: =I17-I18 -> 32621.58 | K25: =K17-K18 -> 305619.77 | M25: =M17-M18 -> 354535.18 | O25: =O17-O18 -> 348538.53 | Q25: =Q17-Q18 -> 0 | S25: =S17-S18 -> 0 | U25: =U17-U18 -> 0 | W25: =W17-W18 -> 0 | Y25: =Y17-Y18 -> 0 | AA25: =AA17-AA18 -> 3064267.5
B26: Resultado Financeiro | C26: =SUMIF(MVTO!$C$3:$C$72,"Rec_Fin",MVTO!$F$3:$F$72)-SUMIF(MVTO!$C$3:$C$72,"Desp_Fin",MVTO!$F$3:$F$72) -> -1591.56 | E26: =SUMIF(MVTO!$C$3:$C$72,"Rec_Fin",MVTO!$G$3:$G$72)-SUMIF(MVTO!$C$3:$C$72,"Desp_Fin",MVTO!$G$3:$G$72) -> -14276.99 | G26: =SUMIF(MVTO!$C$3:$C$72,"Rec_Fin",MVTO!$H$3:$H$72)-SUMIF(MVTO!$C$3:$C$72,"Desp_Fin",MVTO!$H$3:$H$72) -> 2353.2 | I26: =SUMIF(MVTO!$C$3:$C$72,"Rec_Fin",MVTO!$I$3:$I$72)-SUMIF(MVTO!$C$3:$C$72,"Desp_Fin",MVTO!$I$3:$I$72) -> -2204.02 | K26: =SUMIF(MVTO!$C$3:$C$72,"Rec_Fin",MVTO!$J$3:$J$72)-SUMIF(MVTO!$C$3:$C$72,"Desp_Fin",MVTO!$J$3:$J$72) -> 731.82 | M26: =SUMIF(MVTO!$C$3:$C$72,"Rec_Fin",MVTO!$K$3:$K$72)-SUMIF(MVTO!$C$3:$C$72,"Desp_Fin",MVTO!$K$3:$K$72) -> -1926 | O26: =SUMIF(MVTO!$C$3:$C$72,"Rec_Fin",MVTO!$L$3:$L$72)-SUMIF(MVTO!$C$3:$C$72,"Desp_Fin",MVTO!$L$3:$L$72) -> -25.33 | Q26: =SUMIF(MVTO!$C$3:$C$72,"Rec_Fin",MVTO!$M$3:$M$72)-SUMIF(MVTO!$C$3:$C$72,"Desp_Fin",MVTO!$M$3:$M$72) -> 0 | S26: =SUMIF(MVTO!$C$3:$C$72,"Rec_Fin",MVTO!$N$3:$N$72)-SUMIF(MVTO!$C$3:$C$72,"Desp_Fin",MVTO!$N$3:$N$72) -> 0 | U26: =SUMIF(MVTO!$C$3:$C$72,"Rec_Fin",MVTO!$O$3:$NO$72)-SUMIF(MVTO!$C$3:$C$72,"Desp_Fin",MVTO!$O$3:$O$72) -> 0 | W26: =SUMIF(MVTO!$C$3:$C$72,"Rec_Fin",MVTO!$P$3:$NP$72)-SUMIF(MVTO!$C$3:$C$72,"Desp_Fin",MVTO!$P$3:$P$72) -> 0 | Y26: =SUMIF(MVTO!$C$3:$C$72,"Rec_Fin",MVTO!$Q$3:$NQ$72)-SUMIF(MVTO!$C$3:$C$72,"Desp_Fin",MVTO!$Q$3:QP$72) -> 0 | AA26: =SUMIF(MVTO!$C$3:$C$72,"Rec_Fin",MVTO!$R$3:$R$72)-SUMIF(MVTO!$C$3:$C$72,"Desp_Fin",MVTO!$R$3:$R$72) -> -169.84
B27: I.R | C27: =SUMIF(MVTO!$C$3:$C$72,"Imp_IR",MVTO!$F$3:$F$72) -> 56026.96 | E27: =SUMIF(MVTO!$C$3:$C$72,"Imp_IR",MVTO!$G$3:$G$72) -> 56026.96 | G27: =SUMIF(MVTO!$C$3:$C$72,"Imp_IR",MVTO!$H$3:$H$72) -> 56026.96 | I27: =SUMIF(MVTO!$C$3:$C$72,"Imp_IR",MVTO!$I$3:$I$72) -> 51706.17 | K27: =SUMIF(MVTO!$C$3:$C$72,"Imp_IR",MVTO!$J$3:$J$72) -> 51706.17 | M27: =SUMIF(MVTO!$C$3:$C$72,"Imp_IR",MVTO!$K$3:$K$72) -> 51706.17 | O27: =SUMIF(MVTO!$C$3:$C$72,"Imp_IR",MVTO!$L$3:$L$72) -> 52473.69 | Q27: =SUMIF(MVTO!$C$3:$C$72,"Imp_IR",MVTO!$M$3:$M$72) -> 0 | S27: =SUMIF(MVTO!$C$3:$C$72,"Imp_IR",MVTO!$N$3:$N$72) -> 0 | U27: =SUMIF(MVTO!$C$3:$C$72,"Imp_IR",MVTO!$O$3:$O$72) -> 0 | W27: =SUMIF(MVTO!$C$3:$C$72,"Imp_IR",MVTO!$P$3:$P$72) -> 0 | Y27: =SUMIF(MVTO!$C$3:$C$72,"Imp_IR",MVTO!$Q$3:$Q$72) -> 0 | AA27: =SUMIF(MVTO!$C$3:$C$72,"Imp_IR",MVTO!$R$3:$R$72) -> 375673.08
B28: Lucro líquido | C28: =C25+C26-C27 -> 9304.9 | E28: =E25+E26-E27 -> 1252438.6 | G28: =G25+G26-G27 -> 579480.17 | I28: =I25+I26-I27 -> -21288.61 | K28: =K25+K26-K27 -> 254645.42 | M28: =M25+M26-M27 -> 300903.01 | O28: =O25+O26-O27 -> 296039.51 | Q28: =Q25+Q26-Q27 -> 0 | S28: =S25+S26-S27 -> 0 | U28: =U25+U26-U27 -> 0 | W28: =W25+W26-W27 -> 0 | Y28: =Y25+Y26-Y27 -> 0 | AA28: =AA25+AA26-AA27 -> 2688424.6
B29: PgtoEmpréstimos | C29: =SUMIF(MVTO!$C$3:$C$72,"Empréstimo",MVTO!$F$3:$F$72) -> 36969.98 | E29: =SUMIF(MVTO!$C$3:$C$72,"Empréstimo",MVTO!$G$3:$G$72) -> 36969.98 | G29: =SUMIF(MVTO!$C$3:$C$72,"Empréstimo",MVTO!$H$3:$H$72) -> 36969.98 | I29: =SUMIF(MVTO!$C$3:$C$72,"Empréstimo",MVTO!$I$3:$I$72) -> 36969.98 | K29: =SUMIF(MVTO!$C$3:$C$72,"Empréstimo",MVTO!$J$3:$J$72) -> 36969.98 | M29: =SUMIF(MVTO!$C$3:$C$72,"Empréstimo",MVTO!$K$3:$K$72) -> 36969.98 | O29: =SUMIF(MVTO!$C$3:$C$72,"Empréstimo",MVTO!$L$3:$L$72) -> 36969.98 | Q29: =SUMIF(MVTO!$C$3:$C$72,"Empréstimo",MVTO!$M$3:$M$72) -> 0 | S29: =SUMIF(MVTO!$C$3:$C$72,"Empréstimo",MVTO!$N$3:$N$72) -> 0 | U29: =SUMIF(MVTO!$C$3:$C$72,"Empréstimo",MVTO!$O$3:$O$72) -> 0 | W29: =SUMIF(MVTO!$C$3:$C$72,"Empréstimo",MVTO!$P$3:$P$72) -> 0 | Y29: =SUMIF(MVTO!$C$3:$C$72,"Empréstimo",MVTO!$Q$3:$Q$72) -> 0 | AA29: =SUMIF(MVTO!$C$3:$C$72,"Empréstimo",MVTO!$R$3:$R$72) -> 258789.86
B30: Envio a Ligadas | C30: =SUMIF(MVTO!$C$3:$C$72,"Ligadas_S",MVTO!$F$3:$F$72) -> 0 | E30: =SUMIF(MVTO!$C$3:$C$72,"Ligadas_S",MVTO!$G$3:$G$72) -> 0 | G30: =SUMIF(MVTO!$C$3:$C$72,"Ligadas_S",MVTO!$H$3:$H$72) -> 0 | I30: =SUMIF(MVTO!$C$3:$C$72,"Ligadas_S",MVTO!$I$3:$I$72) -> 64958 | K30: =SUMIF(MVTO!$C$3:$C$72,"Ligadas_S",MVTO!$J$3:$J$72) -> 1718.36 | M30: =SUMIF(MVTO!$C$3:$C$72,"Ligadas_S",MVTO!$K$3:$K$72) -> 2949.85 | O30: =SUMIF(MVTO!$C$3:$C$72,"Ligadas_S",MVTO!$L$3:$L$72) -> 8538.8 | Q30: =SUMIF(MVTO!$C$3:$C$72,"Ligadas_S",MVTO!$M$3:$M$72) -> 0 | S30: =SUMIF(MVTO!$C$3:$C$72,"Ligadas_S",MVTO!$N$3:$N$72) -> 0 | U30: =SUMIF(MVTO!$C$3:$C$72,"Ligadas_S",MVTO!$O$3:$O$72) -> 0 | W30: =SUMIF(MVTO!$C$3:$C$72,"Ligadas_S",MVTO!$P$3:$P$72) -> 0 | Y30: =SUMIF(MVTO!$C$3:$C$72,"Ligadas_S",MVTO!$Q$3:$Q$72) -> 0 | AA30: =SUMIF(MVTO!$C$3:$C$72,"Ligadas_S",MVTO!$R$3:$R$72) -> 78165.01
B31: Invest/imobilizado | C31: =SUMIF(MVTO!$C$3:$C$72,"Imobilizado",MVTO!$F$3:$F$72) -> 0 | E31: =SUMIF(MVTO!$C$3:$C$72,"Imobilizado",MVTO!$G$3:$G$72) -> 738529.3 | G31: =SUMIF(MVTO!$C$3:$C$72,"Imobilizado",MVTO!$H$3:$H$72) -> 71960.51 | I31: =SUMIF(MVTO!$C$3:$C$72,"Imobilizado",MVTO!$I$3:$I$72) -> 89270.36 | K31: =SUMIF(MVTO!$C$3:$C$72,"Imobilizado",MVTO!$J$3:$J$72) -> 170256.26 | M31: =SUMIF(MVTO!$C$3:$C$72,"Imobilizado",MVTO!$K$3:$K$72) -> 103527.88 | O31: =SUMIF(MVTO!$C$3:$C$72,"Imobilizado",MVTO!$L$3:$L$72) -> 86668.64 | Q31: =SUMIF(MVTO!$C$3:$C$72,"Imobilizado",MVTO!$M$3:$M$72) -> 0 | S31: =SUMIF(MVTO!$C$3:$C$72,"Imobilizado",MVTO!$N$3:$N$72) -> 0 | U31: =SUMIF(MVTO!$C$3:$C$72,"Imobilizado",MVTO!$O$3:$O$72) -> 0 | W31: =SUMIF(MVTO!$C$3:$C$72,"Imobilizado",MVTO!$P$3:$P$72) -> 0 | Y31: =SUMIF(MVTO!$C$3:$C$72,"Imobilizado",MVTO!$Q$3:$Q$72) -> 0 | AA31: =SUMIF(MVTO!$C$3:$C$72,"Imobilizado",MVTO!$R$3:$R$72) -> 1260212.9
B32: Entrada de Recursos | C32: =SUMIF(MVTO!$C$3:$C$72,"Ligadas_E",MVTO!$F$3:$F$72)+ SUMIF(MVTO!$C$3:$C$72,"Recursos_E",MVTO!$F$3:$F$72) -> 0 | E32: =SUMIF(MVTO!$C$3:$C$72,"Ligadas_E",MVTO!$G$3:$G$72)+ SUMIF(MVTO!$C$3:$C$72,"Recursos_E",MVTO!$G$3:$G$72) -> 0 | G32: =SUMIF(MVTO!$C$3:$C$72,"Ligadas_E",MVTO!$H$3:$H$72)+ SUMIF(MVTO!$C$3:$C$72,"Recursos_E",MVTO!$H$3:$H$72) -> 0 | I32: =SUMIF(MVTO!$C$3:$C$72,"Ligadas_E",MVTO!$I$3:$I$72)+ SUMIF(MVTO!$C$3:$C$72,"Recursos_E",MVTO!$I$3:$I$72) -> 0 | K32: =SUMIF(MVTO!$C$3:$C$72,"Ligadas_E",MVTO!$J$3:$J$72)+ SUMIF(MVTO!$C$3:$C$72,"Recursos_E",MVTO!$J$3:$J$72) -> 33958 | M32: =SUMIF(MVTO!$C$3:$C$72,"Ligadas_E",MVTO!$K$3:$K$72)+ SUMIF(MVTO!$C$3:$C$72,"Recursos_E",MVTO!$K$3:$K$72) -> 13456.21 | O32: =SUMIF(MVTO!$C$3:$C$72,"Ligadas_E",MVTO!$L$3:$L$72)+ SUMIF(MVTO!$C$3:$C$72,"Recursos_E",MVTO!$L$3:$L$72) -> 0 | Q32: =SUMIF(MVTO!$C$3:$C$72,"Ligadas_E",MVTO!$M$3:$M$72)+ SUMIF(MVTO!$C$3:$C$72,"Recursos_E",MVTO!$M$3:$M$72) -> 0 | S32: =SUMIF(MVTO!$C$3:$C$72,"Ligadas_E",MVTO!$N$3:$N$72)+ SUMIF(MVTO!$C$3:$C$72,"Recursos_E",MVTO!$N$3:$N$72) -> 0 | U32: =SUMIF(MVTO!$C$3:$C$72,"Ligadas_E",MVTO!$O$3:$O$72)+ SUMIF(MVTO!$C$3:$C$72,"Recursos_E",MVTO!$O$3:$O$72) -> 0 | W32: =SUMIF(MVTO!$C$3:$C$72,"Ligadas_E",MVTO!$P$3:$P$72)+ SUMIF(MVTO!$C$3:$C$72,"Recursos_E",MVTO!$P$3:$P$72) -> 0 | Y32: =SUMIF(MVTO!$C$3:$C$72,"Ligadas_E",MVTO!$Q$3:$Q$72)+ SUMIF(MVTO!$C$3:$C$72,"Recursos_E",MVTO!$Q$3:$Q$72) -> 0 | AA32: =SUMIF(MVTO!$C$3:$C$72,"Ligadas_E",MVTO!$R$3:$R$72)+ SUMIF(MVTO!$C$3:$C$72,"Recursos_E",MVTO!$R$3:$R$72) -> 0
B33: Resultado | C33: =C28-C29-C30-C31+C32 -> -27665.08 | E33: =E28-E29-E30-E31+E32 -> 476939.36 | G33: =G28-G29-G30-G31+G32 -> 470549.68 | I33: =I28-I29-I30-I31+I32 -> -212486.95 | K33: =K28-K29-K30-K31+K32 -> 79658.82 | M33: =M28-M29-M30-M31+M32 -> 170911.51 | O33: =O28-O29-O30-O31+O32 -> 163862.09 | Q33: =Q28-Q29-Q30-Q31+Q32 -> 0 | S33: =S28-S29-S30-S31+S32 -> 0 | U33: =U28-U29-U30+U32-U31 -> 0 | W33: =W28-W29-W30+W32-W31 -> 0 | Y33: =Y28-Y29-Y30+Y32 -> 0 | AA33: =AA28-AA29-AA30-AA31+AA32 -> 1091256.8
B34: Total de Sócios | C34: =SUM(C35:C38) -> 154723.57 | E34: =SUM(E35:E38) -> 144347.06 | G34: =SUM(G35:G38) -> 153061.82 | I34: =SUM(I35:I38) -> 210317.77 | K34: =SUM(K35:K38) -> 188092.63 | M34: =SUM(M35:M38) -> 240937.51 | O34: =SUM(O35:O38) -> 249673.47 | Q34: =SUM(Q35:Q38) -> 0 | S34: =SUM(S35:S38) -> 0 | U34: =SUM(U35:U38) -> 0 | W34: =SUM(W35:W38) -> 0 | Y34: =SUM(Y35:Y38) -> 0 | AA34: =SUM(AA35:AA38) -> 1341153.8
B35: Sócio_Diego | C35: =SUMIF(MVTO!$C$3:$C$72,"Sócio_Diego",MVTO!$F$3:$F$72) -> 27593.81 | E35: =SUMIF(MVTO!$C$3:$C$72,"Sócio_Diego",MVTO!$G$3:$G$72) -> 32612.75 | G35: =SUMIF(MVTO!$C$3:$C$72,"Sócio_Diego",MVTO!$H$3:$H$72) -> 32502.67 | I35: =SUMIF(MVTO!$C$3:$C$72,"Sócio_Diego",MVTO!$I$3:$I$72) -> 38690.86 | K35: =SUMIF(MVTO!$C$3:$C$72,"Sócio_Diego",MVTO!$J$3:$J$72) -> 45261.76 | M35: =SUMIF(MVTO!$C$3:$C$72,"Sócio_Diego",MVTO!$K$3:$K$72) -> 48231.95 | O35: =SUMIF(MVTO!$C$3:$C$72,"Sócio_Diego",MVTO!$L$3:$L$72) -> 34675.74 | Q35: =SUMIF(MVTO!$C$3:$C$72,"Sócio_Diego",MVTO!$M$3:$M$72) -> 0 | S35: =SUMIF(MVTO!$C$3:$C$72,"Sócio_Diego",MVTO!$N$3:$N$72) -> 0 | U35: =SUMIF(MVTO!$C$3:$C$72,"Sócio_Diego",MVTO!$O$3:$O$72) -> 0 | W35: =SUMIF(MVTO!$C$3:$C$72,"Sócio_Diego",MVTO!$P$3:$P$72) -> 0 | Y35: =SUMIF(MVTO!$C$3:$C$72,"Sócio_Diego",MVTO!$Q$3:$Q$72) -> 0 | AA35: =SUMIF(MVTO!$C$3:$C$72,"Sócio_Diego",MVTO!$R$3:$R$72) -> 259569.54
B36: Sócio_Thiago | C36: =SUMIF(MVTO!$C$3:$C$72,"Sócio_Thiago",MVTO!$F$3:$F$72) -> 46201.36 | E36: =SUMIF(MVTO!$C$3:$C$72,"Sócio_Thiago",MVTO!$G$3:$G$72) -> 31008.67 | G36: =SUMIF(MVTO!$C$3:$C$72,"Sócio_Thiago",MVTO!$H$3:$H$72) -> 36008.64 | I36: =SUMIF(MVTO!$C$3:$C$72,"Sócio_Thiago",MVTO!$I$3:$I$72) -> 41008.64 | K36: =SUMIF(MVTO!$C$3:$C$72,"Sócio_Thiago",MVTO!$J$3:$J$72) -> 46295.6 | M36: =SUMIF(MVTO!$C$3:$C$72,"Sócio_Thiago",MVTO!$K$3:$K$72) -> 92249.19 | O36: =SUMIF(MVTO!$C$3:$C$72,"Sócio_Thiago",MVTO!$L$3:$L$72) -> 64470.93 | Q36: =SUMIF(MVTO!$C$3:$C$72,"Sócio_Thiago",MVTO!$M$3:$M$72) -> 0 | S36: =SUMIF(MVTO!$C$3:$C$72,"Sócio_Thiago",MVTO!$N$3:$N$72) -> 0 | U36: =SUMIF(MVTO!$C$3:$C$72,"Sócio_Thiago",MVTO!$O$3:$O$72) -> 0 | W36: =SUMIF(MVTO!$C$3:$C$72,"Sócio_Thiago",MVTO!$P$3:$P$72) -> 0 | Y36: =SUMIF(MVTO!$C$3:$C$72,"Sócio_Thiago",MVTO!$Q$3:$Q$72) -> 0 | AA36: =SUMIF(MVTO!$C$3:$C$72,"Sócio_Thiago",MVTO!$R$3:$R$72) -> 357243.03
B37: Sócio_Pátricia | C37: =SUMIF(MVTO!$C$3:$C$72,"Sócio_Pátricia",MVTO!$F$3:$F$72) -> 42328.4 | E37: =SUMIF(MVTO!$C$3:$C$72,"Sócio_Pátricia",MVTO!$G$3:$G$72) -> 32152.64 | G37: =SUMIF(MVTO!$C$3:$C$72,"Sócio_Pátricia",MVTO!$H$3:$H$72) -> 31008.67 | I37: =SUMIF(MVTO!$C$3:$C$72,"Sócio_Pátricia",MVTO!$I$3:$I$72) -> 46038.11 | K37: =SUMIF(MVTO!$C$3:$C$72,"Sócio_Pátricia",MVTO!$J$3:$J$72) -> 46008.67 | M37: =SUMIF(MVTO!$C$3:$C$72,"Sócio_Pátricia",MVTO!$K$3:$K$72) -> 46052.85 | O37: =SUMIF(MVTO!$C$3:$C$72,"Sócio_Pátricia",MVTO!$L$3:$L$72) -> 37200 | Q37: =SUMIF(MVTO!$C$3:$C$72,"Sócio_Pátricia",MVTO!$M$3:$M$72) -> 0 | S37: =SUMIF(MVTO!$C$3:$C$72,"Sócio_Pátricia",MVTO!N$3:$N$72) -> 0 | U37: =SUMIF(MVTO!$C$3:$C$72,"Sócio_Pátricia",MVTO!$O$3:$O$72) -> 0 | W37: =SUMIF(MVTO!$C$3:$C$72,"Sócio_Pátricia",MVTO!$P$3:$P$72) -> 0 | Y37: =SUMIF(MVTO!$C$3:$C$72,"Sócio_Pátricia",MVTO!$Q$3:$Q$72) -> 0 | AA37: =SUMIF(MVTO!$C$3:$C$72,"Sócio_Pátricia",MVTO!$R$3:$R$72) -> 280789.34
B38: Sócio_Tubertino | C38: =SUMIF(MVTO!$C$3:$C$72,"Sócio_Tubertino",MVTO!$F$3:$F$72) -> 38600 | E38: =SUMIF(MVTO!$C$3:$C$72,"Sócio_Tubertino",MVTO!$G$3:$G$72) -> 48573 | G38: =SUMIF(MVTO!$C$3:$C$72,"Sócio_Tubertino",MVTO!$H$3:$H$72) -> 53541.84 | I38: =SUMIF(MVTO!$C$3:$C$72,"Sócio_Tubertino",MVTO!$I$3:$I$72) -> 84580.16 | K38: =SUMIF(MVTO!$C$3:$C$72,"Sócio_Tubertino",MVTO!$J$3:$J$72) -> 50526.6 | M38: =SUMIF(MVTO!$C$3:$C$72,"Sócio_Tubertino",MVTO!$K$3:$K$72) -> 54403.52 | O38: =SUMIF(MVTO!$C$3:$C$72,"Sócio_Tubertino",MVTO!$L$3:$L$72) -> 113326.8 | Q38: =SUMIF(MVTO!$C$3:$C$72,"Sócio_Tubertino",MVTO!$M$3:$M$72) -> 0 | S38: =SUMIF(MVTO!$C$3:$C$72,"Sócio_Tubertino",MVTO!$N$3:$N$72) -> 0 | U38: =SUMIF(MVTO!$C$3:$C$72,"Sócio_Tubertino",MVTO!$O$3:$O$72) -> 0 | W38: =SUMIF(MVTO!$C$3:$C$72,"Sócio_Tubertino",MVTO!$P$3:$P$72) -> 0 | Y38: =SUMIF(MVTO!$C$3:$C$72,"Sócio_Tubertino",MVTO!$Q$3:$Q$72) -> 0 | AA38: =SUMIF(MVTO!$C$3:$C$72,"Sócio_Tubertino",MVTO!$R$3:$R$72) -> 443551.92
B39: Resultado Final | C39: =C33-C34 -> -182388.65 | E39: =E33-E34 -> 332592.3 | G39: =G33-G34 -> 317487.86 | I39: =I33-I34 -> -422804.72 | K39: =K33-K34 -> -108433.81 | M39: =M33-M34 -> -70026 | O39: =O33-O34 -> -85811.38 | Q39: =Q33-Q34 -> 0 | S39: =S33-S34 -> 0 | U39: =U33-U34 -> 0 | W39: =W33-W34 -> 0 | Y39: =Y33-Y34 -> 0 | AA39: =AA33-AA34 -> -249897.04

Sheet MVTO
B2: Mvto | C2: Rubrica | D2: Conta | E2: Descrição Contrapartida | F2: JANEIRO | G2: FEVEREIRO | H2: MARÇO | I2: ABRIL | J2: MAIO | K2: JUNHO | L2: JULHO | M2: AGOSTO | N2: SETEMBRO | O2: OUTUBRO | P2: NOVEMBRO | Q2: DEZEMBRO | R2: TOTAL
B3: ENTRADA | C3: Cliente_C | D3: 112101 | E3: Clientes a Receber | F3: 19875.28 | G3: 40161.63 | H3: 38795.06 | I3: 26231.38 | J3: 51183.74 | K3: 34086.27 | L3: 40272.17 | R3: =SUM(F3:Q3) -> 250605.53
B4: ENTRADA | C4: Cliente_01 | D4: 112101 | E4: Clientes a Receber 01 | F4: 25000 | G4: 980250.35 | H4: 60836.15 | I4: 2177 | J4: 220742.97 | K4: 40000 | L4: 20000 | R4: =SUM(F4:Q4) -> 1349006.5
B5: ENTRADA | C5: Cliente_02 | D5: 112101 | E5: Clientes a Receber 02 | F5: 100847.05 | G5: 140045.89 | H5: 342469.87 | I5: 12000 | J5: 13425 | K5: 233116.41 | L5: 108332.31 | R5: =SUM(F5:Q5) -> 950236.53
